[17/Jun/2017 16:45:55] INFO [django.server:124] "GET / HTTP/1.1" 200 2187
[17/Jun/2017 16:45:55] INFO [django.server:124] "GET /static/img/favicon-16x16.e45deacf157e.png HTTP/1.1" 200 742
[17/Jun/2017 16:55:02] DEBUG [django.db.backends:91] (0.002) 
            SELECT name, type FROM sqlite_master
            WHERE type in ('table', 'view') AND NOT name='sqlite_sequence'
            ORDER BY name; args=None
[17/Jun/2017 16:55:02] DEBUG [django.db.backends:91] (0.000) SELECT "django_migrations"."app", "django_migrations"."name" FROM "django_migrations"; args=()
[17/Jun/2017 16:55:06] INFO [django.server:124] "GET / HTTP/1.1" 200 2031
[17/Jun/2017 16:55:06] INFO [django.server:124] "GET /static/js/search.js HTTP/1.1" 304 0
[17/Jun/2017 16:55:06] INFO [django.server:124] "GET /static/css/home.css HTTP/1.1" 200 1961
[17/Jun/2017 16:55:06] INFO [django.server:124] "GET /static/js/main-min.js HTTP/1.1" 200 386
[17/Jun/2017 16:55:06] INFO [django.server:124] "GET /static/css/stretchy.css HTTP/1.1" 200 10447
[17/Jun/2017 16:55:06] INFO [django.server:124] "GET /static/css/bootstrap.min.css HTTP/1.1" 200 121200
[17/Jun/2017 16:55:06] INFO [django.server:124] "GET /static/css/typeaheadjs.css HTTP/1.1" 200 2578
[17/Jun/2017 16:55:06] INFO [django.server:124] "GET /static/img/bg.jpg HTTP/1.1" 200 254754
[17/Jun/2017 16:55:06] INFO [django.server:124] "GET /static/img/cd-sprite-1.svg HTTP/1.1" 200 2008
[17/Jun/2017 16:55:07] INFO [django.server:124] "GET /static/img/favicon-16x16.png HTTP/1.1" 200 742
[18/Jun/2017 04:34:35] INFO [django.server:124] "GET / HTTP/1.1" 200 2175
[18/Jun/2017 04:40:35] ERROR [django.request:135] Internal Server Error: /get_item/Loki Prime Chassis/static/css/bootstrap.min.5c7070ef655a.css/
Traceback (most recent call last):
  File "/Library/Python/2.7/site-packages/django/core/handlers/exception.py", line 41, in inner
    response = get_response(request)
  File "/Library/Python/2.7/site-packages/django/core/handlers/base.py", line 187, in _get_response
    response = self.process_exception_by_middleware(e, request)
  File "/Library/Python/2.7/site-packages/django/core/handlers/base.py", line 185, in _get_response
    response = wrapped_callback(request, *callback_args, **callback_kwargs)
  File "/Users/jwcorle/Documents/better_getter/get_item/views.py", line 46, in get_item_details
    return render(request, 'item.html', {'err: True'})
  File "/Library/Python/2.7/site-packages/django/shortcuts.py", line 30, in render
    content = loader.render_to_string(template_name, context, request, using=using)
  File "/Library/Python/2.7/site-packages/django/template/loader.py", line 68, in render_to_string
    return template.render(context, request)
  File "/Library/Python/2.7/site-packages/django/template/backends/django.py", line 64, in render
    context = make_context(context, request, autoescape=self.backend.engine.autoescape)
  File "/Library/Python/2.7/site-packages/django/template/context.py", line 287, in make_context
    raise TypeError('context must be a dict rather than %s.' % context.__class__.__name__)
TypeError: context must be a dict rather than set.
[18/Jun/2017 04:40:35] ERROR [django.request:135] Internal Server Error: /get_item/Loki Prime Chassis/static/css/stretchy.6ade60b89e65.css/
Traceback (most recent call last):
  File "/Library/Python/2.7/site-packages/django/core/handlers/exception.py", line 41, in inner
    response = get_response(request)
  File "/Library/Python/2.7/site-packages/django/core/handlers/base.py", line 187, in _get_response
    response = self.process_exception_by_middleware(e, request)
  File "/Library/Python/2.7/site-packages/django/core/handlers/base.py", line 185, in _get_response
    response = wrapped_callback(request, *callback_args, **callback_kwargs)
  File "/Users/jwcorle/Documents/better_getter/get_item/views.py", line 46, in get_item_details
    return render(request, 'item.html', {'err: True'})
  File "/Library/Python/2.7/site-packages/django/shortcuts.py", line 30, in render
    content = loader.render_to_string(template_name, context, request, using=using)
  File "/Library/Python/2.7/site-packages/django/template/loader.py", line 68, in render_to_string
    return template.render(context, request)
  File "/Library/Python/2.7/site-packages/django/template/backends/django.py", line 64, in render
    context = make_context(context, request, autoescape=self.backend.engine.autoescape)
  File "/Library/Python/2.7/site-packages/django/template/context.py", line 287, in make_context
    raise TypeError('context must be a dict rather than %s.' % context.__class__.__name__)
TypeError: context must be a dict rather than set.
[18/Jun/2017 04:40:35] ERROR [django.request:135] Internal Server Error: /get_item/Loki Prime Chassis/static/css/typeaheadjs.74cbdb0b28ef.css/
Traceback (most recent call last):
  File "/Library/Python/2.7/site-packages/django/core/handlers/exception.py", line 41, in inner
    response = get_response(request)
  File "/Library/Python/2.7/site-packages/django/core/handlers/base.py", line 187, in _get_response
    response = self.process_exception_by_middleware(e, request)
  File "/Library/Python/2.7/site-packages/django/core/handlers/base.py", line 185, in _get_response
    response = wrapped_callback(request, *callback_args, **callback_kwargs)
  File "/Users/jwcorle/Documents/better_getter/get_item/views.py", line 46, in get_item_details
    return render(request, 'item.html', {'err: True'})
  File "/Library/Python/2.7/site-packages/django/shortcuts.py", line 30, in render
    content = loader.render_to_string(template_name, context, request, using=using)
  File "/Library/Python/2.7/site-packages/django/template/loader.py", line 68, in render_to_string
    return template.render(context, request)
  File "/Library/Python/2.7/site-packages/django/template/backends/django.py", line 64, in render
    context = make_context(context, request, autoescape=self.backend.engine.autoescape)
  File "/Library/Python/2.7/site-packages/django/template/context.py", line 287, in make_context
    raise TypeError('context must be a dict rather than %s.' % context.__class__.__name__)
TypeError: context must be a dict rather than set.
[18/Jun/2017 04:40:36] ERROR [django.request:135] Internal Server Error: /get_item/Loki Prime Chassis/static/css/get_item.4a8bbdf4e93e.css/
Traceback (most recent call last):
  File "/Library/Python/2.7/site-packages/django/core/handlers/exception.py", line 41, in inner
    response = get_response(request)
  File "/Library/Python/2.7/site-packages/django/core/handlers/base.py", line 187, in _get_response
    response = self.process_exception_by_middleware(e, request)
  File "/Library/Python/2.7/site-packages/django/core/handlers/base.py", line 185, in _get_response
    response = wrapped_callback(request, *callback_args, **callback_kwargs)
  File "/Users/jwcorle/Documents/better_getter/get_item/views.py", line 46, in get_item_details
    return render(request, 'item.html', {'err: True'})
  File "/Library/Python/2.7/site-packages/django/shortcuts.py", line 30, in render
    content = loader.render_to_string(template_name, context, request, using=using)
  File "/Library/Python/2.7/site-packages/django/template/loader.py", line 68, in render_to_string
    return template.render(context, request)
  File "/Library/Python/2.7/site-packages/django/template/backends/django.py", line 64, in render
    context = make_context(context, request, autoescape=self.backend.engine.autoescape)
  File "/Library/Python/2.7/site-packages/django/template/context.py", line 287, in make_context
    raise TypeError('context must be a dict rather than %s.' % context.__class__.__name__)
TypeError: context must be a dict rather than set.
[18/Jun/2017 04:40:36] ERROR [django.request:135] Internal Server Error: /get_item/Loki Prime Chassis/static/js/jquery.min.4f252523d4af.js/
Traceback (most recent call last):
  File "/Library/Python/2.7/site-packages/django/core/handlers/exception.py", line 41, in inner
    response = get_response(request)
  File "/Library/Python/2.7/site-packages/django/core/handlers/base.py", line 187, in _get_response
    response = self.process_exception_by_middleware(e, request)
  File "/Library/Python/2.7/site-packages/django/core/handlers/base.py", line 185, in _get_response
    response = wrapped_callback(request, *callback_args, **callback_kwargs)
  File "/Users/jwcorle/Documents/better_getter/get_item/views.py", line 46, in get_item_details
    return render(request, 'item.html', {'err: True'})
  File "/Library/Python/2.7/site-packages/django/shortcuts.py", line 30, in render
    content = loader.render_to_string(template_name, context, request, using=using)
  File "/Library/Python/2.7/site-packages/django/template/loader.py", line 68, in render_to_string
    return template.render(context, request)
  File "/Library/Python/2.7/site-packages/django/template/backends/django.py", line 64, in render
    context = make_context(context, request, autoescape=self.backend.engine.autoescape)
  File "/Library/Python/2.7/site-packages/django/template/context.py", line 287, in make_context
    raise TypeError('context must be a dict rather than %s.' % context.__class__.__name__)
TypeError: context must be a dict rather than set.
[18/Jun/2017 04:40:36] ERROR [django.request:135] Internal Server Error: /get_item/Loki Prime Chassis/static/js/bootstrap.min.5869c96cc8f1.js/
Traceback (most recent call last):
  File "/Library/Python/2.7/site-packages/django/core/handlers/exception.py", line 41, in inner
    response = get_response(request)
  File "/Library/Python/2.7/site-packages/django/core/handlers/base.py", line 187, in _get_response
    response = self.process_exception_by_middleware(e, request)
  File "/Library/Python/2.7/site-packages/django/core/handlers/base.py", line 185, in _get_response
    response = wrapped_callback(request, *callback_args, **callback_kwargs)
  File "/Users/jwcorle/Documents/better_getter/get_item/views.py", line 46, in get_item_details
    return render(request, 'item.html', {'err: True'})
  File "/Library/Python/2.7/site-packages/django/shortcuts.py", line 30, in render
    content = loader.render_to_string(template_name, context, request, using=using)
  File "/Library/Python/2.7/site-packages/django/template/loader.py", line 68, in render_to_string
    return template.render(context, request)
  File "/Library/Python/2.7/site-packages/django/template/backends/django.py", line 64, in render
    context = make_context(context, request, autoescape=self.backend.engine.autoescape)
  File "/Library/Python/2.7/site-packages/django/template/context.py", line 287, in make_context
    raise TypeError('context must be a dict rather than %s.' % context.__class__.__name__)
TypeError: context must be a dict rather than set.
[18/Jun/2017 04:40:37] ERROR [django.request:135] Internal Server Error: /get_item/Loki Prime Chassis/static/js/typeahead.fd054c48bcd9.js/
Traceback (most recent call last):
  File "/Library/Python/2.7/site-packages/django/core/handlers/exception.py", line 41, in inner
    response = get_response(request)
  File "/Library/Python/2.7/site-packages/django/core/handlers/base.py", line 187, in _get_response
    response = self.process_exception_by_middleware(e, request)
  File "/Library/Python/2.7/site-packages/django/core/handlers/base.py", line 185, in _get_response
    response = wrapped_callback(request, *callback_args, **callback_kwargs)
  File "/Users/jwcorle/Documents/better_getter/get_item/views.py", line 46, in get_item_details
    return render(request, 'item.html', {'err: True'})
  File "/Library/Python/2.7/site-packages/django/shortcuts.py", line 30, in render
    content = loader.render_to_string(template_name, context, request, using=using)
  File "/Library/Python/2.7/site-packages/django/template/loader.py", line 68, in render_to_string
    return template.render(context, request)
  File "/Library/Python/2.7/site-packages/django/template/backends/django.py", line 64, in render
    context = make_context(context, request, autoescape=self.backend.engine.autoescape)
  File "/Library/Python/2.7/site-packages/django/template/context.py", line 287, in make_context
    raise TypeError('context must be a dict rather than %s.' % context.__class__.__name__)
TypeError: context must be a dict rather than set.
[18/Jun/2017 04:40:37] ERROR [django.request:135] Internal Server Error: /get_item/Loki Prime Chassis/static/js/search.7d707a66c25f.js/
Traceback (most recent call last):
  File "/Library/Python/2.7/site-packages/django/core/handlers/exception.py", line 41, in inner
    response = get_response(request)
  File "/Library/Python/2.7/site-packages/django/core/handlers/base.py", line 187, in _get_response
    response = self.process_exception_by_middleware(e, request)
  File "/Library/Python/2.7/site-packages/django/core/handlers/base.py", line 185, in _get_response
    response = wrapped_callback(request, *callback_args, **callback_kwargs)
  File "/Users/jwcorle/Documents/better_getter/get_item/views.py", line 46, in get_item_details
    return render(request, 'item.html', {'err: True'})
  File "/Library/Python/2.7/site-packages/django/shortcuts.py", line 30, in render
    content = loader.render_to_string(template_name, context, request, using=using)
  File "/Library/Python/2.7/site-packages/django/template/loader.py", line 68, in render_to_string
    return template.render(context, request)
  File "/Library/Python/2.7/site-packages/django/template/backends/django.py", line 64, in render
    context = make_context(context, request, autoescape=self.backend.engine.autoescape)
  File "/Library/Python/2.7/site-packages/django/template/context.py", line 287, in make_context
    raise TypeError('context must be a dict rather than %s.' % context.__class__.__name__)
TypeError: context must be a dict rather than set.
[18/Jun/2017 04:40:37] ERROR [django.request:135] Internal Server Error: /get_item/Loki Prime Chassis/static/js/modernizr.1258d3cdc715.js/
Traceback (most recent call last):
  File "/Library/Python/2.7/site-packages/django/core/handlers/exception.py", line 41, in inner
    response = get_response(request)
  File "/Library/Python/2.7/site-packages/django/core/handlers/base.py", line 187, in _get_response
    response = self.process_exception_by_middleware(e, request)
  File "/Library/Python/2.7/site-packages/django/core/handlers/base.py", line 185, in _get_response
    response = wrapped_callback(request, *callback_args, **callback_kwargs)
  File "/Users/jwcorle/Documents/better_getter/get_item/views.py", line 46, in get_item_details
    return render(request, 'item.html', {'err: True'})
  File "/Library/Python/2.7/site-packages/django/shortcuts.py", line 30, in render
    content = loader.render_to_string(template_name, context, request, using=using)
  File "/Library/Python/2.7/site-packages/django/template/loader.py", line 68, in render_to_string
    return template.render(context, request)
  File "/Library/Python/2.7/site-packages/django/template/backends/django.py", line 64, in render
    context = make_context(context, request, autoescape=self.backend.engine.autoescape)
  File "/Library/Python/2.7/site-packages/django/template/context.py", line 287, in make_context
    raise TypeError('context must be a dict rather than %s.' % context.__class__.__name__)
TypeError: context must be a dict rather than set.
[18/Jun/2017 04:40:38] ERROR [django.request:135] Internal Server Error: /get_item/Loki Prime Chassis/static/js/main-min.943e47719b21.js/
Traceback (most recent call last):
  File "/Library/Python/2.7/site-packages/django/core/handlers/exception.py", line 41, in inner
    response = get_response(request)
  File "/Library/Python/2.7/site-packages/django/core/handlers/base.py", line 187, in _get_response
    response = self.process_exception_by_middleware(e, request)
  File "/Library/Python/2.7/site-packages/django/core/handlers/base.py", line 185, in _get_response
    response = wrapped_callback(request, *callback_args, **callback_kwargs)
  File "/Users/jwcorle/Documents/better_getter/get_item/views.py", line 46, in get_item_details
    return render(request, 'item.html', {'err: True'})
  File "/Library/Python/2.7/site-packages/django/shortcuts.py", line 30, in render
    content = loader.render_to_string(template_name, context, request, using=using)
  File "/Library/Python/2.7/site-packages/django/template/loader.py", line 68, in render_to_string
    return template.render(context, request)
  File "/Library/Python/2.7/site-packages/django/template/backends/django.py", line 64, in render
    context = make_context(context, request, autoescape=self.backend.engine.autoescape)
  File "/Library/Python/2.7/site-packages/django/template/context.py", line 287, in make_context
    raise TypeError('context must be a dict rather than %s.' % context.__class__.__name__)
TypeError: context must be a dict rather than set.
[18/Jun/2017 04:40:38] ERROR [django.request:135] Internal Server Error: /get_item/Loki Prime Chassis/static/img/plat.884aa1f89f92.png/
Traceback (most recent call last):
  File "/Library/Python/2.7/site-packages/django/core/handlers/exception.py", line 41, in inner
    response = get_response(request)
  File "/Library/Python/2.7/site-packages/django/core/handlers/base.py", line 187, in _get_response
    response = self.process_exception_by_middleware(e, request)
  File "/Library/Python/2.7/site-packages/django/core/handlers/base.py", line 185, in _get_response
    response = wrapped_callback(request, *callback_args, **callback_kwargs)
  File "/Users/jwcorle/Documents/better_getter/get_item/views.py", line 46, in get_item_details
    return render(request, 'item.html', {'err: True'})
  File "/Library/Python/2.7/site-packages/django/shortcuts.py", line 30, in render
    content = loader.render_to_string(template_name, context, request, using=using)
  File "/Library/Python/2.7/site-packages/django/template/loader.py", line 68, in render_to_string
    return template.render(context, request)
  File "/Library/Python/2.7/site-packages/django/template/backends/django.py", line 64, in render
    context = make_context(context, request, autoescape=self.backend.engine.autoescape)
  File "/Library/Python/2.7/site-packages/django/template/context.py", line 287, in make_context
    raise TypeError('context must be a dict rather than %s.' % context.__class__.__name__)
TypeError: context must be a dict rather than set.
[18/Jun/2017 04:40:38] ERROR [django.request:135] Internal Server Error: /get_item/Loki Prime Chassis/static/img/duc.1727a9df825d.png/
Traceback (most recent call last):
  File "/Library/Python/2.7/site-packages/django/core/handlers/exception.py", line 41, in inner
    response = get_response(request)
  File "/Library/Python/2.7/site-packages/django/core/handlers/base.py", line 187, in _get_response
    response = self.process_exception_by_middleware(e, request)
  File "/Library/Python/2.7/site-packages/django/core/handlers/base.py", line 185, in _get_response
    response = wrapped_callback(request, *callback_args, **callback_kwargs)
  File "/Users/jwcorle/Documents/better_getter/get_item/views.py", line 46, in get_item_details
    return render(request, 'item.html', {'err: True'})
  File "/Library/Python/2.7/site-packages/django/shortcuts.py", line 30, in render
    content = loader.render_to_string(template_name, context, request, using=using)
  File "/Library/Python/2.7/site-packages/django/template/loader.py", line 68, in render_to_string
    return template.render(context, request)
  File "/Library/Python/2.7/site-packages/django/template/backends/django.py", line 64, in render
    context = make_context(context, request, autoescape=self.backend.engine.autoescape)
  File "/Library/Python/2.7/site-packages/django/template/context.py", line 287, in make_context
    raise TypeError('context must be a dict rather than %s.' % context.__class__.__name__)
TypeError: context must be a dict rather than set.
[18/Jun/2017 04:40:39] ERROR [django.request:135] Internal Server Error: /get_item/Loki Prime Chassis/static/img/favicon-16x16.e45deacf157e.png/
Traceback (most recent call last):
  File "/Library/Python/2.7/site-packages/django/core/handlers/exception.py", line 41, in inner
    response = get_response(request)
  File "/Library/Python/2.7/site-packages/django/core/handlers/base.py", line 187, in _get_response
    response = self.process_exception_by_middleware(e, request)
  File "/Library/Python/2.7/site-packages/django/core/handlers/base.py", line 185, in _get_response
    response = wrapped_callback(request, *callback_args, **callback_kwargs)
  File "/Users/jwcorle/Documents/better_getter/get_item/views.py", line 46, in get_item_details
    return render(request, 'item.html', {'err: True'})
  File "/Library/Python/2.7/site-packages/django/shortcuts.py", line 30, in render
    content = loader.render_to_string(template_name, context, request, using=using)
  File "/Library/Python/2.7/site-packages/django/template/loader.py", line 68, in render_to_string
    return template.render(context, request)
  File "/Library/Python/2.7/site-packages/django/template/backends/django.py", line 64, in render
    context = make_context(context, request, autoescape=self.backend.engine.autoescape)
  File "/Library/Python/2.7/site-packages/django/template/context.py", line 287, in make_context
    raise TypeError('context must be a dict rather than %s.' % context.__class__.__name__)
TypeError: context must be a dict rather than set.
[18/Jun/2017 04:40:39] ERROR [django.request:135] Internal Server Error: /get_item/Loki Prime Chassis/static/img/favicon-32x32.d59b1d998588.png/
Traceback (most recent call last):
  File "/Library/Python/2.7/site-packages/django/core/handlers/exception.py", line 41, in inner
    response = get_response(request)
  File "/Library/Python/2.7/site-packages/django/core/handlers/base.py", line 187, in _get_response
    response = self.process_exception_by_middleware(e, request)
  File "/Library/Python/2.7/site-packages/django/core/handlers/base.py", line 185, in _get_response
    response = wrapped_callback(request, *callback_args, **callback_kwargs)
  File "/Users/jwcorle/Documents/better_getter/get_item/views.py", line 46, in get_item_details
    return render(request, 'item.html', {'err: True'})
  File "/Library/Python/2.7/site-packages/django/shortcuts.py", line 30, in render
    content = loader.render_to_string(template_name, context, request, using=using)
  File "/Library/Python/2.7/site-packages/django/template/loader.py", line 68, in render_to_string
    return template.render(context, request)
  File "/Library/Python/2.7/site-packages/django/template/backends/django.py", line 64, in render
    context = make_context(context, request, autoescape=self.backend.engine.autoescape)
  File "/Library/Python/2.7/site-packages/django/template/context.py", line 287, in make_context
    raise TypeError('context must be a dict rather than %s.' % context.__class__.__name__)
TypeError: context must be a dict rather than set.
[18/Jun/2017 04:40:48] ERROR [django.request:135] Internal Server Error: /get_item/Loki Prime Chassis/static/css/bootstrap.min.5c7070ef655a.css/
Traceback (most recent call last):
  File "/Library/Python/2.7/site-packages/django/core/handlers/exception.py", line 41, in inner
    response = get_response(request)
  File "/Library/Python/2.7/site-packages/django/core/handlers/base.py", line 187, in _get_response
    response = self.process_exception_by_middleware(e, request)
  File "/Library/Python/2.7/site-packages/django/core/handlers/base.py", line 185, in _get_response
    response = wrapped_callback(request, *callback_args, **callback_kwargs)
  File "/Users/jwcorle/Documents/better_getter/get_item/views.py", line 46, in get_item_details
    return render(request, 'item.html', {'err: True'})
  File "/Library/Python/2.7/site-packages/django/shortcuts.py", line 30, in render
    content = loader.render_to_string(template_name, context, request, using=using)
  File "/Library/Python/2.7/site-packages/django/template/loader.py", line 68, in render_to_string
    return template.render(context, request)
  File "/Library/Python/2.7/site-packages/django/template/backends/django.py", line 64, in render
    context = make_context(context, request, autoescape=self.backend.engine.autoescape)
  File "/Library/Python/2.7/site-packages/django/template/context.py", line 287, in make_context
    raise TypeError('context must be a dict rather than %s.' % context.__class__.__name__)
TypeError: context must be a dict rather than set.
[18/Jun/2017 04:40:48] ERROR [django.request:135] Internal Server Error: /get_item/Loki Prime Chassis/static/css/stretchy.6ade60b89e65.css/
Traceback (most recent call last):
  File "/Library/Python/2.7/site-packages/django/core/handlers/exception.py", line 41, in inner
    response = get_response(request)
  File "/Library/Python/2.7/site-packages/django/core/handlers/base.py", line 187, in _get_response
    response = self.process_exception_by_middleware(e, request)
  File "/Library/Python/2.7/site-packages/django/core/handlers/base.py", line 185, in _get_response
    response = wrapped_callback(request, *callback_args, **callback_kwargs)
  File "/Users/jwcorle/Documents/better_getter/get_item/views.py", line 46, in get_item_details
    return render(request, 'item.html', {'err: True'})
  File "/Library/Python/2.7/site-packages/django/shortcuts.py", line 30, in render
    content = loader.render_to_string(template_name, context, request, using=using)
  File "/Library/Python/2.7/site-packages/django/template/loader.py", line 68, in render_to_string
    return template.render(context, request)
  File "/Library/Python/2.7/site-packages/django/template/backends/django.py", line 64, in render
    context = make_context(context, request, autoescape=self.backend.engine.autoescape)
  File "/Library/Python/2.7/site-packages/django/template/context.py", line 287, in make_context
    raise TypeError('context must be a dict rather than %s.' % context.__class__.__name__)
TypeError: context must be a dict rather than set.
[18/Jun/2017 04:40:48] ERROR [django.request:135] Internal Server Error: /get_item/Loki Prime Chassis/static/css/typeaheadjs.74cbdb0b28ef.css/
Traceback (most recent call last):
  File "/Library/Python/2.7/site-packages/django/core/handlers/exception.py", line 41, in inner
    response = get_response(request)
  File "/Library/Python/2.7/site-packages/django/core/handlers/base.py", line 187, in _get_response
    response = self.process_exception_by_middleware(e, request)
  File "/Library/Python/2.7/site-packages/django/core/handlers/base.py", line 185, in _get_response
    response = wrapped_callback(request, *callback_args, **callback_kwargs)
  File "/Users/jwcorle/Documents/better_getter/get_item/views.py", line 46, in get_item_details
    return render(request, 'item.html', {'err: True'})
  File "/Library/Python/2.7/site-packages/django/shortcuts.py", line 30, in render
    content = loader.render_to_string(template_name, context, request, using=using)
  File "/Library/Python/2.7/site-packages/django/template/loader.py", line 68, in render_to_string
    return template.render(context, request)
  File "/Library/Python/2.7/site-packages/django/template/backends/django.py", line 64, in render
    context = make_context(context, request, autoescape=self.backend.engine.autoescape)
  File "/Library/Python/2.7/site-packages/django/template/context.py", line 287, in make_context
    raise TypeError('context must be a dict rather than %s.' % context.__class__.__name__)
TypeError: context must be a dict rather than set.
[18/Jun/2017 04:40:49] ERROR [django.request:135] Internal Server Error: /get_item/Loki Prime Chassis/static/css/get_item.4a8bbdf4e93e.css/
Traceback (most recent call last):
  File "/Library/Python/2.7/site-packages/django/core/handlers/exception.py", line 41, in inner
    response = get_response(request)
  File "/Library/Python/2.7/site-packages/django/core/handlers/base.py", line 187, in _get_response
    response = self.process_exception_by_middleware(e, request)
  File "/Library/Python/2.7/site-packages/django/core/handlers/base.py", line 185, in _get_response
    response = wrapped_callback(request, *callback_args, **callback_kwargs)
  File "/Users/jwcorle/Documents/better_getter/get_item/views.py", line 46, in get_item_details
    return render(request, 'item.html', {'err: True'})
  File "/Library/Python/2.7/site-packages/django/shortcuts.py", line 30, in render
    content = loader.render_to_string(template_name, context, request, using=using)
  File "/Library/Python/2.7/site-packages/django/template/loader.py", line 68, in render_to_string
    return template.render(context, request)
  File "/Library/Python/2.7/site-packages/django/template/backends/django.py", line 64, in render
    context = make_context(context, request, autoescape=self.backend.engine.autoescape)
  File "/Library/Python/2.7/site-packages/django/template/context.py", line 287, in make_context
    raise TypeError('context must be a dict rather than %s.' % context.__class__.__name__)
TypeError: context must be a dict rather than set.
[18/Jun/2017 04:41:19] ERROR [django.request:135] Internal Server Error: /get_item/Loki Prime Chassis/static/css/bootstrap.min.5c7070ef655a.css/
Traceback (most recent call last):
  File "/Library/Python/2.7/site-packages/django/core/handlers/exception.py", line 41, in inner
    response = get_response(request)
  File "/Library/Python/2.7/site-packages/django/core/handlers/base.py", line 187, in _get_response
    response = self.process_exception_by_middleware(e, request)
  File "/Library/Python/2.7/site-packages/django/core/handlers/base.py", line 185, in _get_response
    response = wrapped_callback(request, *callback_args, **callback_kwargs)
  File "/Users/jwcorle/Documents/better_getter/get_item/views.py", line 46, in get_item_details
    return render(request, 'item.html', {'err: True'})
  File "/Library/Python/2.7/site-packages/django/shortcuts.py", line 30, in render
    content = loader.render_to_string(template_name, context, request, using=using)
  File "/Library/Python/2.7/site-packages/django/template/loader.py", line 68, in render_to_string
    return template.render(context, request)
  File "/Library/Python/2.7/site-packages/django/template/backends/django.py", line 64, in render
    context = make_context(context, request, autoescape=self.backend.engine.autoescape)
  File "/Library/Python/2.7/site-packages/django/template/context.py", line 287, in make_context
    raise TypeError('context must be a dict rather than %s.' % context.__class__.__name__)
TypeError: context must be a dict rather than set.
[18/Jun/2017 04:41:19] ERROR [django.request:135] Internal Server Error: /get_item/Loki Prime Chassis/static/css/stretchy.6ade60b89e65.css/
Traceback (most recent call last):
  File "/Library/Python/2.7/site-packages/django/core/handlers/exception.py", line 41, in inner
    response = get_response(request)
  File "/Library/Python/2.7/site-packages/django/core/handlers/base.py", line 187, in _get_response
    response = self.process_exception_by_middleware(e, request)
  File "/Library/Python/2.7/site-packages/django/core/handlers/base.py", line 185, in _get_response
    response = wrapped_callback(request, *callback_args, **callback_kwargs)
  File "/Users/jwcorle/Documents/better_getter/get_item/views.py", line 46, in get_item_details
    return render(request, 'item.html', {'err: True'})
  File "/Library/Python/2.7/site-packages/django/shortcuts.py", line 30, in render
    content = loader.render_to_string(template_name, context, request, using=using)
  File "/Library/Python/2.7/site-packages/django/template/loader.py", line 68, in render_to_string
    return template.render(context, request)
  File "/Library/Python/2.7/site-packages/django/template/backends/django.py", line 64, in render
    context = make_context(context, request, autoescape=self.backend.engine.autoescape)
  File "/Library/Python/2.7/site-packages/django/template/context.py", line 287, in make_context
    raise TypeError('context must be a dict rather than %s.' % context.__class__.__name__)
TypeError: context must be a dict rather than set.
[18/Jun/2017 04:41:20] ERROR [django.request:135] Internal Server Error: /get_item/Loki Prime Chassis/static/css/typeaheadjs.74cbdb0b28ef.css/
Traceback (most recent call last):
  File "/Library/Python/2.7/site-packages/django/core/handlers/exception.py", line 41, in inner
    response = get_response(request)
  File "/Library/Python/2.7/site-packages/django/core/handlers/base.py", line 187, in _get_response
    response = self.process_exception_by_middleware(e, request)
  File "/Library/Python/2.7/site-packages/django/core/handlers/base.py", line 185, in _get_response
    response = wrapped_callback(request, *callback_args, **callback_kwargs)
  File "/Users/jwcorle/Documents/better_getter/get_item/views.py", line 46, in get_item_details
    return render(request, 'item.html', {'err: True'})
  File "/Library/Python/2.7/site-packages/django/shortcuts.py", line 30, in render
    content = loader.render_to_string(template_name, context, request, using=using)
  File "/Library/Python/2.7/site-packages/django/template/loader.py", line 68, in render_to_string
    return template.render(context, request)
  File "/Library/Python/2.7/site-packages/django/template/backends/django.py", line 64, in render
    context = make_context(context, request, autoescape=self.backend.engine.autoescape)
  File "/Library/Python/2.7/site-packages/django/template/context.py", line 287, in make_context
    raise TypeError('context must be a dict rather than %s.' % context.__class__.__name__)
TypeError: context must be a dict rather than set.
[18/Jun/2017 04:41:20] ERROR [django.request:135] Internal Server Error: /get_item/Loki Prime Chassis/static/css/get_item.4a8bbdf4e93e.css/
Traceback (most recent call last):
  File "/Library/Python/2.7/site-packages/django/core/handlers/exception.py", line 41, in inner
    response = get_response(request)
  File "/Library/Python/2.7/site-packages/django/core/handlers/base.py", line 187, in _get_response
    response = self.process_exception_by_middleware(e, request)
  File "/Library/Python/2.7/site-packages/django/core/handlers/base.py", line 185, in _get_response
    response = wrapped_callback(request, *callback_args, **callback_kwargs)
  File "/Users/jwcorle/Documents/better_getter/get_item/views.py", line 46, in get_item_details
    return render(request, 'item.html', {'err: True'})
  File "/Library/Python/2.7/site-packages/django/shortcuts.py", line 30, in render
    content = loader.render_to_string(template_name, context, request, using=using)
  File "/Library/Python/2.7/site-packages/django/template/loader.py", line 68, in render_to_string
    return template.render(context, request)
  File "/Library/Python/2.7/site-packages/django/template/backends/django.py", line 64, in render
    context = make_context(context, request, autoescape=self.backend.engine.autoescape)
  File "/Library/Python/2.7/site-packages/django/template/context.py", line 287, in make_context
    raise TypeError('context must be a dict rather than %s.' % context.__class__.__name__)
TypeError: context must be a dict rather than set.
[18/Jun/2017 04:41:20] ERROR [django.request:135] Internal Server Error: /get_item/Loki Prime Chassis/static/js/jquery.min.4f252523d4af.js/
Traceback (most recent call last):
  File "/Library/Python/2.7/site-packages/django/core/handlers/exception.py", line 41, in inner
    response = get_response(request)
  File "/Library/Python/2.7/site-packages/django/core/handlers/base.py", line 187, in _get_response
    response = self.process_exception_by_middleware(e, request)
  File "/Library/Python/2.7/site-packages/django/core/handlers/base.py", line 185, in _get_response
    response = wrapped_callback(request, *callback_args, **callback_kwargs)
  File "/Users/jwcorle/Documents/better_getter/get_item/views.py", line 46, in get_item_details
    return render(request, 'item.html', {'err: True'})
  File "/Library/Python/2.7/site-packages/django/shortcuts.py", line 30, in render
    content = loader.render_to_string(template_name, context, request, using=using)
  File "/Library/Python/2.7/site-packages/django/template/loader.py", line 68, in render_to_string
    return template.render(context, request)
  File "/Library/Python/2.7/site-packages/django/template/backends/django.py", line 64, in render
    context = make_context(context, request, autoescape=self.backend.engine.autoescape)
  File "/Library/Python/2.7/site-packages/django/template/context.py", line 287, in make_context
    raise TypeError('context must be a dict rather than %s.' % context.__class__.__name__)
TypeError: context must be a dict rather than set.
[18/Jun/2017 04:41:21] ERROR [django.request:135] Internal Server Error: /get_item/Loki Prime Chassis/static/js/bootstrap.min.5869c96cc8f1.js/
Traceback (most recent call last):
  File "/Library/Python/2.7/site-packages/django/core/handlers/exception.py", line 41, in inner
    response = get_response(request)
  File "/Library/Python/2.7/site-packages/django/core/handlers/base.py", line 187, in _get_response
    response = self.process_exception_by_middleware(e, request)
  File "/Library/Python/2.7/site-packages/django/core/handlers/base.py", line 185, in _get_response
    response = wrapped_callback(request, *callback_args, **callback_kwargs)
  File "/Users/jwcorle/Documents/better_getter/get_item/views.py", line 46, in get_item_details
    return render(request, 'item.html', {'err: True'})
  File "/Library/Python/2.7/site-packages/django/shortcuts.py", line 30, in render
    content = loader.render_to_string(template_name, context, request, using=using)
  File "/Library/Python/2.7/site-packages/django/template/loader.py", line 68, in render_to_string
    return template.render(context, request)
  File "/Library/Python/2.7/site-packages/django/template/backends/django.py", line 64, in render
    context = make_context(context, request, autoescape=self.backend.engine.autoescape)
  File "/Library/Python/2.7/site-packages/django/template/context.py", line 287, in make_context
    raise TypeError('context must be a dict rather than %s.' % context.__class__.__name__)
TypeError: context must be a dict rather than set.
[18/Jun/2017 04:41:21] ERROR [django.request:135] Internal Server Error: /get_item/Loki Prime Chassis/static/js/typeahead.fd054c48bcd9.js/
Traceback (most recent call last):
  File "/Library/Python/2.7/site-packages/django/core/handlers/exception.py", line 41, in inner
    response = get_response(request)
  File "/Library/Python/2.7/site-packages/django/core/handlers/base.py", line 187, in _get_response
    response = self.process_exception_by_middleware(e, request)
  File "/Library/Python/2.7/site-packages/django/core/handlers/base.py", line 185, in _get_response
    response = wrapped_callback(request, *callback_args, **callback_kwargs)
  File "/Users/jwcorle/Documents/better_getter/get_item/views.py", line 46, in get_item_details
    return render(request, 'item.html', {'err: True'})
  File "/Library/Python/2.7/site-packages/django/shortcuts.py", line 30, in render
    content = loader.render_to_string(template_name, context, request, using=using)
  File "/Library/Python/2.7/site-packages/django/template/loader.py", line 68, in render_to_string
    return template.render(context, request)
  File "/Library/Python/2.7/site-packages/django/template/backends/django.py", line 64, in render
    context = make_context(context, request, autoescape=self.backend.engine.autoescape)
  File "/Library/Python/2.7/site-packages/django/template/context.py", line 287, in make_context
    raise TypeError('context must be a dict rather than %s.' % context.__class__.__name__)
TypeError: context must be a dict rather than set.
[18/Jun/2017 04:41:21] ERROR [django.request:135] Internal Server Error: /get_item/Loki Prime Chassis/static/js/search.7d707a66c25f.js/
Traceback (most recent call last):
  File "/Library/Python/2.7/site-packages/django/core/handlers/exception.py", line 41, in inner
    response = get_response(request)
  File "/Library/Python/2.7/site-packages/django/core/handlers/base.py", line 187, in _get_response
    response = self.process_exception_by_middleware(e, request)
  File "/Library/Python/2.7/site-packages/django/core/handlers/base.py", line 185, in _get_response
    response = wrapped_callback(request, *callback_args, **callback_kwargs)
  File "/Users/jwcorle/Documents/better_getter/get_item/views.py", line 46, in get_item_details
    return render(request, 'item.html', {'err: True'})
  File "/Library/Python/2.7/site-packages/django/shortcuts.py", line 30, in render
    content = loader.render_to_string(template_name, context, request, using=using)
  File "/Library/Python/2.7/site-packages/django/template/loader.py", line 68, in render_to_string
    return template.render(context, request)
  File "/Library/Python/2.7/site-packages/django/template/backends/django.py", line 64, in render
    context = make_context(context, request, autoescape=self.backend.engine.autoescape)
  File "/Library/Python/2.7/site-packages/django/template/context.py", line 287, in make_context
    raise TypeError('context must be a dict rather than %s.' % context.__class__.__name__)
TypeError: context must be a dict rather than set.
[18/Jun/2017 04:41:22] ERROR [django.request:135] Internal Server Error: /get_item/Loki Prime Chassis/static/js/modernizr.1258d3cdc715.js/
Traceback (most recent call last):
  File "/Library/Python/2.7/site-packages/django/core/handlers/exception.py", line 41, in inner
    response = get_response(request)
  File "/Library/Python/2.7/site-packages/django/core/handlers/base.py", line 187, in _get_response
    response = self.process_exception_by_middleware(e, request)
  File "/Library/Python/2.7/site-packages/django/core/handlers/base.py", line 185, in _get_response
    response = wrapped_callback(request, *callback_args, **callback_kwargs)
  File "/Users/jwcorle/Documents/better_getter/get_item/views.py", line 46, in get_item_details
    return render(request, 'item.html', {'err: True'})
  File "/Library/Python/2.7/site-packages/django/shortcuts.py", line 30, in render
    content = loader.render_to_string(template_name, context, request, using=using)
  File "/Library/Python/2.7/site-packages/django/template/loader.py", line 68, in render_to_string
    return template.render(context, request)
  File "/Library/Python/2.7/site-packages/django/template/backends/django.py", line 64, in render
    context = make_context(context, request, autoescape=self.backend.engine.autoescape)
  File "/Library/Python/2.7/site-packages/django/template/context.py", line 287, in make_context
    raise TypeError('context must be a dict rather than %s.' % context.__class__.__name__)
TypeError: context must be a dict rather than set.
[18/Jun/2017 04:41:22] ERROR [django.request:135] Internal Server Error: /get_item/Loki Prime Chassis/static/js/main-min.943e47719b21.js/
Traceback (most recent call last):
  File "/Library/Python/2.7/site-packages/django/core/handlers/exception.py", line 41, in inner
    response = get_response(request)
  File "/Library/Python/2.7/site-packages/django/core/handlers/base.py", line 187, in _get_response
    response = self.process_exception_by_middleware(e, request)
  File "/Library/Python/2.7/site-packages/django/core/handlers/base.py", line 185, in _get_response
    response = wrapped_callback(request, *callback_args, **callback_kwargs)
  File "/Users/jwcorle/Documents/better_getter/get_item/views.py", line 46, in get_item_details
    return render(request, 'item.html', {'err: True'})
  File "/Library/Python/2.7/site-packages/django/shortcuts.py", line 30, in render
    content = loader.render_to_string(template_name, context, request, using=using)
  File "/Library/Python/2.7/site-packages/django/template/loader.py", line 68, in render_to_string
    return template.render(context, request)
  File "/Library/Python/2.7/site-packages/django/template/backends/django.py", line 64, in render
    context = make_context(context, request, autoescape=self.backend.engine.autoescape)
  File "/Library/Python/2.7/site-packages/django/template/context.py", line 287, in make_context
    raise TypeError('context must be a dict rather than %s.' % context.__class__.__name__)
TypeError: context must be a dict rather than set.
[18/Jun/2017 04:41:22] ERROR [django.request:135] Internal Server Error: /get_item/Loki Prime Chassis/static/img/plat.884aa1f89f92.png/
Traceback (most recent call last):
  File "/Library/Python/2.7/site-packages/django/core/handlers/exception.py", line 41, in inner
    response = get_response(request)
  File "/Library/Python/2.7/site-packages/django/core/handlers/base.py", line 187, in _get_response
    response = self.process_exception_by_middleware(e, request)
  File "/Library/Python/2.7/site-packages/django/core/handlers/base.py", line 185, in _get_response
    response = wrapped_callback(request, *callback_args, **callback_kwargs)
  File "/Users/jwcorle/Documents/better_getter/get_item/views.py", line 46, in get_item_details
    return render(request, 'item.html', {'err: True'})
  File "/Library/Python/2.7/site-packages/django/shortcuts.py", line 30, in render
    content = loader.render_to_string(template_name, context, request, using=using)
  File "/Library/Python/2.7/site-packages/django/template/loader.py", line 68, in render_to_string
    return template.render(context, request)
  File "/Library/Python/2.7/site-packages/django/template/backends/django.py", line 64, in render
    context = make_context(context, request, autoescape=self.backend.engine.autoescape)
  File "/Library/Python/2.7/site-packages/django/template/context.py", line 287, in make_context
    raise TypeError('context must be a dict rather than %s.' % context.__class__.__name__)
TypeError: context must be a dict rather than set.
[18/Jun/2017 04:41:23] ERROR [django.request:135] Internal Server Error: /get_item/Loki Prime Chassis/static/img/duc.1727a9df825d.png/
Traceback (most recent call last):
  File "/Library/Python/2.7/site-packages/django/core/handlers/exception.py", line 41, in inner
    response = get_response(request)
  File "/Library/Python/2.7/site-packages/django/core/handlers/base.py", line 187, in _get_response
    response = self.process_exception_by_middleware(e, request)
  File "/Library/Python/2.7/site-packages/django/core/handlers/base.py", line 185, in _get_response
    response = wrapped_callback(request, *callback_args, **callback_kwargs)
  File "/Users/jwcorle/Documents/better_getter/get_item/views.py", line 46, in get_item_details
    return render(request, 'item.html', {'err: True'})
  File "/Library/Python/2.7/site-packages/django/shortcuts.py", line 30, in render
    content = loader.render_to_string(template_name, context, request, using=using)
  File "/Library/Python/2.7/site-packages/django/template/loader.py", line 68, in render_to_string
    return template.render(context, request)
  File "/Library/Python/2.7/site-packages/django/template/backends/django.py", line 64, in render
    context = make_context(context, request, autoescape=self.backend.engine.autoescape)
  File "/Library/Python/2.7/site-packages/django/template/context.py", line 287, in make_context
    raise TypeError('context must be a dict rather than %s.' % context.__class__.__name__)
TypeError: context must be a dict rather than set.
[18/Jun/2017 04:41:23] ERROR [django.request:135] Internal Server Error: /get_item/Loki Prime Chassis/static/img/favicon-16x16.e45deacf157e.png/
Traceback (most recent call last):
  File "/Library/Python/2.7/site-packages/django/core/handlers/exception.py", line 41, in inner
    response = get_response(request)
  File "/Library/Python/2.7/site-packages/django/core/handlers/base.py", line 187, in _get_response
    response = self.process_exception_by_middleware(e, request)
  File "/Library/Python/2.7/site-packages/django/core/handlers/base.py", line 185, in _get_response
    response = wrapped_callback(request, *callback_args, **callback_kwargs)
  File "/Users/jwcorle/Documents/better_getter/get_item/views.py", line 46, in get_item_details
    return render(request, 'item.html', {'err: True'})
  File "/Library/Python/2.7/site-packages/django/shortcuts.py", line 30, in render
    content = loader.render_to_string(template_name, context, request, using=using)
  File "/Library/Python/2.7/site-packages/django/template/loader.py", line 68, in render_to_string
    return template.render(context, request)
  File "/Library/Python/2.7/site-packages/django/template/backends/django.py", line 64, in render
    context = make_context(context, request, autoescape=self.backend.engine.autoescape)
  File "/Library/Python/2.7/site-packages/django/template/context.py", line 287, in make_context
    raise TypeError('context must be a dict rather than %s.' % context.__class__.__name__)
TypeError: context must be a dict rather than set.
[18/Jun/2017 04:41:23] ERROR [django.request:135] Internal Server Error: /get_item/Loki Prime Chassis/static/img/favicon-32x32.d59b1d998588.png/
Traceback (most recent call last):
  File "/Library/Python/2.7/site-packages/django/core/handlers/exception.py", line 41, in inner
    response = get_response(request)
  File "/Library/Python/2.7/site-packages/django/core/handlers/base.py", line 187, in _get_response
    response = self.process_exception_by_middleware(e, request)
  File "/Library/Python/2.7/site-packages/django/core/handlers/base.py", line 185, in _get_response
    response = wrapped_callback(request, *callback_args, **callback_kwargs)
  File "/Users/jwcorle/Documents/better_getter/get_item/views.py", line 46, in get_item_details
    return render(request, 'item.html', {'err: True'})
  File "/Library/Python/2.7/site-packages/django/shortcuts.py", line 30, in render
    content = loader.render_to_string(template_name, context, request, using=using)
  File "/Library/Python/2.7/site-packages/django/template/loader.py", line 68, in render_to_string
    return template.render(context, request)
  File "/Library/Python/2.7/site-packages/django/template/backends/django.py", line 64, in render
    context = make_context(context, request, autoescape=self.backend.engine.autoescape)
  File "/Library/Python/2.7/site-packages/django/template/context.py", line 287, in make_context
    raise TypeError('context must be a dict rather than %s.' % context.__class__.__name__)
TypeError: context must be a dict rather than set.
[18/Jun/2017 04:46:36] ERROR [django.request:135] Internal Server Error: /get_item/Loki Prime Chassis/
Traceback (most recent call last):
  File "/Library/Python/2.7/site-packages/django/core/handlers/exception.py", line 41, in inner
    response = get_response(request)
  File "/Library/Python/2.7/site-packages/django/core/handlers/base.py", line 187, in _get_response
    response = self.process_exception_by_middleware(e, request)
  File "/Library/Python/2.7/site-packages/django/core/handlers/base.py", line 185, in _get_response
    response = wrapped_callback(request, *callback_args, **callback_kwargs)
  File "/Users/jwcorle/Documents/better_getter/get_item/views.py", line 161, in get_item_details
    return render(request, 'item.html', context)
  File "/Library/Python/2.7/site-packages/django/shortcuts.py", line 30, in render
    content = loader.render_to_string(template_name, context, request, using=using)
  File "/Library/Python/2.7/site-packages/django/template/loader.py", line 68, in render_to_string
    return template.render(context, request)
  File "/Library/Python/2.7/site-packages/django/template/backends/django.py", line 66, in render
    return self.template.render(context)
  File "/Library/Python/2.7/site-packages/django/template/base.py", line 207, in render
    return self._render(context)
  File "/Library/Python/2.7/site-packages/django/template/base.py", line 199, in _render
    return self.nodelist.render(context)
  File "/Library/Python/2.7/site-packages/django/template/base.py", line 990, in render
    bit = node.render_annotated(context)
  File "/Library/Python/2.7/site-packages/django/template/base.py", line 957, in render_annotated
    return self.render(context)
  File "/Library/Python/2.7/site-packages/django/template/loader_tags.py", line 177, in render
    return compiled_parent._render(context)
  File "/Library/Python/2.7/site-packages/django/template/base.py", line 199, in _render
    return self.nodelist.render(context)
  File "/Library/Python/2.7/site-packages/django/template/base.py", line 990, in render
    bit = node.render_annotated(context)
  File "/Library/Python/2.7/site-packages/django/template/base.py", line 957, in render_annotated
    return self.render(context)
  File "/Library/Python/2.7/site-packages/django/templatetags/static.py", line 105, in render
    url = self.url(context)
  File "/Library/Python/2.7/site-packages/django/templatetags/static.py", line 102, in url
    return self.handle_simple(path)
  File "/Library/Python/2.7/site-packages/django/templatetags/static.py", line 117, in handle_simple
    return staticfiles_storage.url(path)
  File "/Library/Python/2.7/site-packages/django/contrib/staticfiles/storage.py", line 162, in url
    return self._url(self.stored_name, name, force)
  File "/Library/Python/2.7/site-packages/django/contrib/staticfiles/storage.py", line 141, in _url
    hashed_name = hashed_name_func(*args)
  File "/Library/Python/2.7/site-packages/django/contrib/staticfiles/storage.py", line 432, in stored_name
    raise ValueError("Missing staticfiles manifest entry for '%s'" % clean_name)
ValueError: Missing staticfiles manifest entry for 'css/bootstrap.min.css'
[18/Jun/2017 04:46:36] WARNING [django.request:152] Not Found: /favicon.ico
[18/Jun/2017 04:59:58] ERROR [django.request:135] Internal Server Error: /
Traceback (most recent call last):
  File "/Library/Python/2.7/site-packages/django/core/handlers/exception.py", line 41, in inner
    response = get_response(request)
  File "/Library/Python/2.7/site-packages/django/core/handlers/base.py", line 217, in _get_response
    response = self.process_exception_by_middleware(e, request)
  File "/Library/Python/2.7/site-packages/django/core/handlers/base.py", line 215, in _get_response
    response = response.render()
  File "/Library/Python/2.7/site-packages/django/template/response.py", line 107, in render
    self.content = self.rendered_content
  File "/Library/Python/2.7/site-packages/django/template/response.py", line 82, in rendered_content
    template = self.resolve_template(self.template_name)
  File "/Library/Python/2.7/site-packages/django/template/response.py", line 64, in resolve_template
    return select_template(template, using=self.using)
  File "/Library/Python/2.7/site-packages/django/template/loader.py", line 44, in select_template
    engines = _engine_list(using)
  File "/Library/Python/2.7/site-packages/django/template/loader.py", line 72, in _engine_list
    return engines.all() if using is None else [engines[using]]
  File "/Library/Python/2.7/site-packages/django/template/utils.py", line 89, in all
    return [self[alias] for alias in self]
  File "/Library/Python/2.7/site-packages/django/template/utils.py", line 80, in __getitem__
    engine = engine_cls(params)
  File "/Library/Python/2.7/site-packages/django/template/backends/django.py", line 32, in __init__
    self.engine = Engine(self.dirs, self.app_dirs, **options)
  File "/Library/Python/2.7/site-packages/django/template/engine.py", line 35, in __init__
    "app_dirs must not be set when loaders is defined.")
ImproperlyConfigured: app_dirs must not be set when loaders is defined.
[18/Jun/2017 04:59:58] ERROR [django.request:135] Internal Server Error: /
Traceback (most recent call last):
  File "/Library/Python/2.7/site-packages/django/core/handlers/exception.py", line 41, in inner
    response = get_response(request)
  File "/Library/Python/2.7/site-packages/django/utils/deprecation.py", line 140, in __call__
    response = self.get_response(request)
  File "/Library/Python/2.7/site-packages/django/core/handlers/exception.py", line 43, in inner
    response = response_for_exception(request, exc)
  File "/Library/Python/2.7/site-packages/django/core/handlers/exception.py", line 93, in response_for_exception
    response = handle_uncaught_exception(request, get_resolver(get_urlconf()), sys.exc_info())
  File "/Library/Python/2.7/site-packages/django/core/handlers/exception.py", line 143, in handle_uncaught_exception
    return callback(request, **param_dict)
  File "/Library/Python/2.7/site-packages/django/utils/decorators.py", line 149, in _wrapped_view
    response = view_func(request, *args, **kwargs)
  File "/Library/Python/2.7/site-packages/django/views/defaults.py", line 68, in server_error
    template = loader.get_template(template_name)
  File "/Library/Python/2.7/site-packages/django/template/loader.py", line 18, in get_template
    engines = _engine_list(using)
  File "/Library/Python/2.7/site-packages/django/template/loader.py", line 72, in _engine_list
    return engines.all() if using is None else [engines[using]]
  File "/Library/Python/2.7/site-packages/django/template/utils.py", line 89, in all
    return [self[alias] for alias in self]
  File "/Library/Python/2.7/site-packages/django/template/utils.py", line 80, in __getitem__
    engine = engine_cls(params)
  File "/Library/Python/2.7/site-packages/django/template/backends/django.py", line 32, in __init__
    self.engine = Engine(self.dirs, self.app_dirs, **options)
  File "/Library/Python/2.7/site-packages/django/template/engine.py", line 35, in __init__
    "app_dirs must not be set when loaders is defined.")
ImproperlyConfigured: app_dirs must not be set when loaders is defined.
[18/Jun/2017 04:59:58] ERROR [django.request:135] Internal Server Error: /
Traceback (most recent call last):
  File "/Library/Python/2.7/site-packages/django/core/handlers/exception.py", line 41, in inner
    response = get_response(request)
  File "/Library/Python/2.7/site-packages/django/utils/deprecation.py", line 140, in __call__
    response = self.get_response(request)
  File "/Library/Python/2.7/site-packages/django/core/handlers/exception.py", line 43, in inner
    response = response_for_exception(request, exc)
  File "/Library/Python/2.7/site-packages/django/core/handlers/exception.py", line 93, in response_for_exception
    response = handle_uncaught_exception(request, get_resolver(get_urlconf()), sys.exc_info())
  File "/Library/Python/2.7/site-packages/django/core/handlers/exception.py", line 143, in handle_uncaught_exception
    return callback(request, **param_dict)
  File "/Library/Python/2.7/site-packages/django/utils/decorators.py", line 149, in _wrapped_view
    response = view_func(request, *args, **kwargs)
  File "/Library/Python/2.7/site-packages/django/views/defaults.py", line 68, in server_error
    template = loader.get_template(template_name)
  File "/Library/Python/2.7/site-packages/django/template/loader.py", line 18, in get_template
    engines = _engine_list(using)
  File "/Library/Python/2.7/site-packages/django/template/loader.py", line 72, in _engine_list
    return engines.all() if using is None else [engines[using]]
  File "/Library/Python/2.7/site-packages/django/template/utils.py", line 89, in all
    return [self[alias] for alias in self]
  File "/Library/Python/2.7/site-packages/django/template/utils.py", line 80, in __getitem__
    engine = engine_cls(params)
  File "/Library/Python/2.7/site-packages/django/template/backends/django.py", line 32, in __init__
    self.engine = Engine(self.dirs, self.app_dirs, **options)
  File "/Library/Python/2.7/site-packages/django/template/engine.py", line 35, in __init__
    "app_dirs must not be set when loaders is defined.")
ImproperlyConfigured: app_dirs must not be set when loaders is defined.
[18/Jun/2017 04:59:58] ERROR [django.request:135] Internal Server Error: /
Traceback (most recent call last):
  File "/Library/Python/2.7/site-packages/django/core/handlers/exception.py", line 41, in inner
    response = get_response(request)
  File "/Library/Python/2.7/site-packages/django/utils/deprecation.py", line 140, in __call__
    response = self.get_response(request)
  File "/Library/Python/2.7/site-packages/django/core/handlers/exception.py", line 43, in inner
    response = response_for_exception(request, exc)
  File "/Library/Python/2.7/site-packages/django/core/handlers/exception.py", line 93, in response_for_exception
    response = handle_uncaught_exception(request, get_resolver(get_urlconf()), sys.exc_info())
  File "/Library/Python/2.7/site-packages/django/core/handlers/exception.py", line 143, in handle_uncaught_exception
    return callback(request, **param_dict)
  File "/Library/Python/2.7/site-packages/django/utils/decorators.py", line 149, in _wrapped_view
    response = view_func(request, *args, **kwargs)
  File "/Library/Python/2.7/site-packages/django/views/defaults.py", line 68, in server_error
    template = loader.get_template(template_name)
  File "/Library/Python/2.7/site-packages/django/template/loader.py", line 18, in get_template
    engines = _engine_list(using)
  File "/Library/Python/2.7/site-packages/django/template/loader.py", line 72, in _engine_list
    return engines.all() if using is None else [engines[using]]
  File "/Library/Python/2.7/site-packages/django/template/utils.py", line 89, in all
    return [self[alias] for alias in self]
  File "/Library/Python/2.7/site-packages/django/template/utils.py", line 80, in __getitem__
    engine = engine_cls(params)
  File "/Library/Python/2.7/site-packages/django/template/backends/django.py", line 32, in __init__
    self.engine = Engine(self.dirs, self.app_dirs, **options)
  File "/Library/Python/2.7/site-packages/django/template/engine.py", line 35, in __init__
    "app_dirs must not be set when loaders is defined.")
ImproperlyConfigured: app_dirs must not be set when loaders is defined.
[18/Jun/2017 04:59:58] ERROR [django.request:135] Internal Server Error: /
Traceback (most recent call last):
  File "/Library/Python/2.7/site-packages/django/core/handlers/exception.py", line 41, in inner
    response = get_response(request)
  File "/Library/Python/2.7/site-packages/django/utils/deprecation.py", line 140, in __call__
    response = self.get_response(request)
  File "/Library/Python/2.7/site-packages/django/core/handlers/exception.py", line 43, in inner
    response = response_for_exception(request, exc)
  File "/Library/Python/2.7/site-packages/django/core/handlers/exception.py", line 93, in response_for_exception
    response = handle_uncaught_exception(request, get_resolver(get_urlconf()), sys.exc_info())
  File "/Library/Python/2.7/site-packages/django/core/handlers/exception.py", line 143, in handle_uncaught_exception
    return callback(request, **param_dict)
  File "/Library/Python/2.7/site-packages/django/utils/decorators.py", line 149, in _wrapped_view
    response = view_func(request, *args, **kwargs)
  File "/Library/Python/2.7/site-packages/django/views/defaults.py", line 68, in server_error
    template = loader.get_template(template_name)
  File "/Library/Python/2.7/site-packages/django/template/loader.py", line 18, in get_template
    engines = _engine_list(using)
  File "/Library/Python/2.7/site-packages/django/template/loader.py", line 72, in _engine_list
    return engines.all() if using is None else [engines[using]]
  File "/Library/Python/2.7/site-packages/django/template/utils.py", line 89, in all
    return [self[alias] for alias in self]
  File "/Library/Python/2.7/site-packages/django/template/utils.py", line 80, in __getitem__
    engine = engine_cls(params)
  File "/Library/Python/2.7/site-packages/django/template/backends/django.py", line 32, in __init__
    self.engine = Engine(self.dirs, self.app_dirs, **options)
  File "/Library/Python/2.7/site-packages/django/template/engine.py", line 35, in __init__
    "app_dirs must not be set when loaders is defined.")
ImproperlyConfigured: app_dirs must not be set when loaders is defined.
[18/Jun/2017 04:59:58] ERROR [django.request:135] Internal Server Error: /
Traceback (most recent call last):
  File "/Library/Python/2.7/site-packages/django/core/handlers/exception.py", line 41, in inner
    response = get_response(request)
  File "/Library/Python/2.7/site-packages/django/utils/deprecation.py", line 140, in __call__
    response = self.get_response(request)
  File "/Library/Python/2.7/site-packages/django/core/handlers/exception.py", line 43, in inner
    response = response_for_exception(request, exc)
  File "/Library/Python/2.7/site-packages/django/core/handlers/exception.py", line 93, in response_for_exception
    response = handle_uncaught_exception(request, get_resolver(get_urlconf()), sys.exc_info())
  File "/Library/Python/2.7/site-packages/django/core/handlers/exception.py", line 143, in handle_uncaught_exception
    return callback(request, **param_dict)
  File "/Library/Python/2.7/site-packages/django/utils/decorators.py", line 149, in _wrapped_view
    response = view_func(request, *args, **kwargs)
  File "/Library/Python/2.7/site-packages/django/views/defaults.py", line 68, in server_error
    template = loader.get_template(template_name)
  File "/Library/Python/2.7/site-packages/django/template/loader.py", line 18, in get_template
    engines = _engine_list(using)
  File "/Library/Python/2.7/site-packages/django/template/loader.py", line 72, in _engine_list
    return engines.all() if using is None else [engines[using]]
  File "/Library/Python/2.7/site-packages/django/template/utils.py", line 89, in all
    return [self[alias] for alias in self]
  File "/Library/Python/2.7/site-packages/django/template/utils.py", line 80, in __getitem__
    engine = engine_cls(params)
  File "/Library/Python/2.7/site-packages/django/template/backends/django.py", line 32, in __init__
    self.engine = Engine(self.dirs, self.app_dirs, **options)
  File "/Library/Python/2.7/site-packages/django/template/engine.py", line 35, in __init__
    "app_dirs must not be set when loaders is defined.")
ImproperlyConfigured: app_dirs must not be set when loaders is defined.
[18/Jun/2017 04:59:58] ERROR [django.request:135] Internal Server Error: /
Traceback (most recent call last):
  File "/Library/Python/2.7/site-packages/django/core/handlers/exception.py", line 41, in inner
    response = get_response(request)
  File "/Library/Python/2.7/site-packages/django/utils/deprecation.py", line 140, in __call__
    response = self.get_response(request)
  File "/Library/Python/2.7/site-packages/django/core/handlers/exception.py", line 43, in inner
    response = response_for_exception(request, exc)
  File "/Library/Python/2.7/site-packages/django/core/handlers/exception.py", line 93, in response_for_exception
    response = handle_uncaught_exception(request, get_resolver(get_urlconf()), sys.exc_info())
  File "/Library/Python/2.7/site-packages/django/core/handlers/exception.py", line 143, in handle_uncaught_exception
    return callback(request, **param_dict)
  File "/Library/Python/2.7/site-packages/django/utils/decorators.py", line 149, in _wrapped_view
    response = view_func(request, *args, **kwargs)
  File "/Library/Python/2.7/site-packages/django/views/defaults.py", line 68, in server_error
    template = loader.get_template(template_name)
  File "/Library/Python/2.7/site-packages/django/template/loader.py", line 18, in get_template
    engines = _engine_list(using)
  File "/Library/Python/2.7/site-packages/django/template/loader.py", line 72, in _engine_list
    return engines.all() if using is None else [engines[using]]
  File "/Library/Python/2.7/site-packages/django/template/utils.py", line 89, in all
    return [self[alias] for alias in self]
  File "/Library/Python/2.7/site-packages/django/template/utils.py", line 80, in __getitem__
    engine = engine_cls(params)
  File "/Library/Python/2.7/site-packages/django/template/backends/django.py", line 32, in __init__
    self.engine = Engine(self.dirs, self.app_dirs, **options)
  File "/Library/Python/2.7/site-packages/django/template/engine.py", line 35, in __init__
    "app_dirs must not be set when loaders is defined.")
ImproperlyConfigured: app_dirs must not be set when loaders is defined.
[18/Jun/2017 04:59:58] ERROR [django.request:135] Internal Server Error: /
Traceback (most recent call last):
  File "/Library/Python/2.7/site-packages/django/core/handlers/exception.py", line 41, in inner
    response = get_response(request)
  File "/Library/Python/2.7/site-packages/django/utils/deprecation.py", line 140, in __call__
    response = self.get_response(request)
  File "/Library/Python/2.7/site-packages/django/core/handlers/exception.py", line 43, in inner
    response = response_for_exception(request, exc)
  File "/Library/Python/2.7/site-packages/django/core/handlers/exception.py", line 93, in response_for_exception
    response = handle_uncaught_exception(request, get_resolver(get_urlconf()), sys.exc_info())
  File "/Library/Python/2.7/site-packages/django/core/handlers/exception.py", line 143, in handle_uncaught_exception
    return callback(request, **param_dict)
  File "/Library/Python/2.7/site-packages/django/utils/decorators.py", line 149, in _wrapped_view
    response = view_func(request, *args, **kwargs)
  File "/Library/Python/2.7/site-packages/django/views/defaults.py", line 68, in server_error
    template = loader.get_template(template_name)
  File "/Library/Python/2.7/site-packages/django/template/loader.py", line 18, in get_template
    engines = _engine_list(using)
  File "/Library/Python/2.7/site-packages/django/template/loader.py", line 72, in _engine_list
    return engines.all() if using is None else [engines[using]]
  File "/Library/Python/2.7/site-packages/django/template/utils.py", line 89, in all
    return [self[alias] for alias in self]
  File "/Library/Python/2.7/site-packages/django/template/utils.py", line 80, in __getitem__
    engine = engine_cls(params)
  File "/Library/Python/2.7/site-packages/django/template/backends/django.py", line 32, in __init__
    self.engine = Engine(self.dirs, self.app_dirs, **options)
  File "/Library/Python/2.7/site-packages/django/template/engine.py", line 35, in __init__
    "app_dirs must not be set when loaders is defined.")
ImproperlyConfigured: app_dirs must not be set when loaders is defined.
[18/Jun/2017 05:00:50] ERROR [django.request:135] Internal Server Error: /
Traceback (most recent call last):
  File "/Library/Python/2.7/site-packages/django/core/handlers/exception.py", line 41, in inner
    response = get_response(request)
  File "/Library/Python/2.7/site-packages/django/core/handlers/base.py", line 217, in _get_response
    response = self.process_exception_by_middleware(e, request)
  File "/Library/Python/2.7/site-packages/django/core/handlers/base.py", line 215, in _get_response
    response = response.render()
  File "/Library/Python/2.7/site-packages/django/template/response.py", line 107, in render
    self.content = self.rendered_content
  File "/Library/Python/2.7/site-packages/django/template/response.py", line 82, in rendered_content
    template = self.resolve_template(self.template_name)
  File "/Library/Python/2.7/site-packages/django/template/response.py", line 64, in resolve_template
    return select_template(template, using=self.using)
  File "/Library/Python/2.7/site-packages/django/template/loader.py", line 44, in select_template
    engines = _engine_list(using)
  File "/Library/Python/2.7/site-packages/django/template/loader.py", line 72, in _engine_list
    return engines.all() if using is None else [engines[using]]
  File "/Library/Python/2.7/site-packages/django/template/utils.py", line 89, in all
    return [self[alias] for alias in self]
  File "/Library/Python/2.7/site-packages/django/template/utils.py", line 80, in __getitem__
    engine = engine_cls(params)
  File "/Library/Python/2.7/site-packages/django/template/backends/django.py", line 32, in __init__
    self.engine = Engine(self.dirs, self.app_dirs, **options)
  File "/Library/Python/2.7/site-packages/django/template/engine.py", line 35, in __init__
    "app_dirs must not be set when loaders is defined.")
ImproperlyConfigured: app_dirs must not be set when loaders is defined.
[18/Jun/2017 05:00:50] ERROR [django.request:135] Internal Server Error: /
Traceback (most recent call last):
  File "/Library/Python/2.7/site-packages/django/core/handlers/exception.py", line 41, in inner
    response = get_response(request)
  File "/Library/Python/2.7/site-packages/django/utils/deprecation.py", line 140, in __call__
    response = self.get_response(request)
  File "/Library/Python/2.7/site-packages/django/core/handlers/exception.py", line 43, in inner
    response = response_for_exception(request, exc)
  File "/Library/Python/2.7/site-packages/django/core/handlers/exception.py", line 93, in response_for_exception
    response = handle_uncaught_exception(request, get_resolver(get_urlconf()), sys.exc_info())
  File "/Library/Python/2.7/site-packages/django/core/handlers/exception.py", line 143, in handle_uncaught_exception
    return callback(request, **param_dict)
  File "/Library/Python/2.7/site-packages/django/utils/decorators.py", line 149, in _wrapped_view
    response = view_func(request, *args, **kwargs)
  File "/Library/Python/2.7/site-packages/django/views/defaults.py", line 68, in server_error
    template = loader.get_template(template_name)
  File "/Library/Python/2.7/site-packages/django/template/loader.py", line 18, in get_template
    engines = _engine_list(using)
  File "/Library/Python/2.7/site-packages/django/template/loader.py", line 72, in _engine_list
    return engines.all() if using is None else [engines[using]]
  File "/Library/Python/2.7/site-packages/django/template/utils.py", line 89, in all
    return [self[alias] for alias in self]
  File "/Library/Python/2.7/site-packages/django/template/utils.py", line 80, in __getitem__
    engine = engine_cls(params)
  File "/Library/Python/2.7/site-packages/django/template/backends/django.py", line 32, in __init__
    self.engine = Engine(self.dirs, self.app_dirs, **options)
  File "/Library/Python/2.7/site-packages/django/template/engine.py", line 35, in __init__
    "app_dirs must not be set when loaders is defined.")
ImproperlyConfigured: app_dirs must not be set when loaders is defined.
[18/Jun/2017 05:00:50] ERROR [django.request:135] Internal Server Error: /
Traceback (most recent call last):
  File "/Library/Python/2.7/site-packages/django/core/handlers/exception.py", line 41, in inner
    response = get_response(request)
  File "/Library/Python/2.7/site-packages/django/utils/deprecation.py", line 140, in __call__
    response = self.get_response(request)
  File "/Library/Python/2.7/site-packages/django/core/handlers/exception.py", line 43, in inner
    response = response_for_exception(request, exc)
  File "/Library/Python/2.7/site-packages/django/core/handlers/exception.py", line 93, in response_for_exception
    response = handle_uncaught_exception(request, get_resolver(get_urlconf()), sys.exc_info())
  File "/Library/Python/2.7/site-packages/django/core/handlers/exception.py", line 143, in handle_uncaught_exception
    return callback(request, **param_dict)
  File "/Library/Python/2.7/site-packages/django/utils/decorators.py", line 149, in _wrapped_view
    response = view_func(request, *args, **kwargs)
  File "/Library/Python/2.7/site-packages/django/views/defaults.py", line 68, in server_error
    template = loader.get_template(template_name)
  File "/Library/Python/2.7/site-packages/django/template/loader.py", line 18, in get_template
    engines = _engine_list(using)
  File "/Library/Python/2.7/site-packages/django/template/loader.py", line 72, in _engine_list
    return engines.all() if using is None else [engines[using]]
  File "/Library/Python/2.7/site-packages/django/template/utils.py", line 89, in all
    return [self[alias] for alias in self]
  File "/Library/Python/2.7/site-packages/django/template/utils.py", line 80, in __getitem__
    engine = engine_cls(params)
  File "/Library/Python/2.7/site-packages/django/template/backends/django.py", line 32, in __init__
    self.engine = Engine(self.dirs, self.app_dirs, **options)
  File "/Library/Python/2.7/site-packages/django/template/engine.py", line 35, in __init__
    "app_dirs must not be set when loaders is defined.")
ImproperlyConfigured: app_dirs must not be set when loaders is defined.
[18/Jun/2017 05:00:50] ERROR [django.request:135] Internal Server Error: /
Traceback (most recent call last):
  File "/Library/Python/2.7/site-packages/django/core/handlers/exception.py", line 41, in inner
    response = get_response(request)
  File "/Library/Python/2.7/site-packages/django/utils/deprecation.py", line 140, in __call__
    response = self.get_response(request)
  File "/Library/Python/2.7/site-packages/django/core/handlers/exception.py", line 43, in inner
    response = response_for_exception(request, exc)
  File "/Library/Python/2.7/site-packages/django/core/handlers/exception.py", line 93, in response_for_exception
    response = handle_uncaught_exception(request, get_resolver(get_urlconf()), sys.exc_info())
  File "/Library/Python/2.7/site-packages/django/core/handlers/exception.py", line 143, in handle_uncaught_exception
    return callback(request, **param_dict)
  File "/Library/Python/2.7/site-packages/django/utils/decorators.py", line 149, in _wrapped_view
    response = view_func(request, *args, **kwargs)
  File "/Library/Python/2.7/site-packages/django/views/defaults.py", line 68, in server_error
    template = loader.get_template(template_name)
  File "/Library/Python/2.7/site-packages/django/template/loader.py", line 18, in get_template
    engines = _engine_list(using)
  File "/Library/Python/2.7/site-packages/django/template/loader.py", line 72, in _engine_list
    return engines.all() if using is None else [engines[using]]
  File "/Library/Python/2.7/site-packages/django/template/utils.py", line 89, in all
    return [self[alias] for alias in self]
  File "/Library/Python/2.7/site-packages/django/template/utils.py", line 80, in __getitem__
    engine = engine_cls(params)
  File "/Library/Python/2.7/site-packages/django/template/backends/django.py", line 32, in __init__
    self.engine = Engine(self.dirs, self.app_dirs, **options)
  File "/Library/Python/2.7/site-packages/django/template/engine.py", line 35, in __init__
    "app_dirs must not be set when loaders is defined.")
ImproperlyConfigured: app_dirs must not be set when loaders is defined.
[18/Jun/2017 05:00:50] ERROR [django.request:135] Internal Server Error: /
Traceback (most recent call last):
  File "/Library/Python/2.7/site-packages/django/core/handlers/exception.py", line 41, in inner
    response = get_response(request)
  File "/Library/Python/2.7/site-packages/django/utils/deprecation.py", line 140, in __call__
    response = self.get_response(request)
  File "/Library/Python/2.7/site-packages/django/core/handlers/exception.py", line 43, in inner
    response = response_for_exception(request, exc)
  File "/Library/Python/2.7/site-packages/django/core/handlers/exception.py", line 93, in response_for_exception
    response = handle_uncaught_exception(request, get_resolver(get_urlconf()), sys.exc_info())
  File "/Library/Python/2.7/site-packages/django/core/handlers/exception.py", line 143, in handle_uncaught_exception
    return callback(request, **param_dict)
  File "/Library/Python/2.7/site-packages/django/utils/decorators.py", line 149, in _wrapped_view
    response = view_func(request, *args, **kwargs)
  File "/Library/Python/2.7/site-packages/django/views/defaults.py", line 68, in server_error
    template = loader.get_template(template_name)
  File "/Library/Python/2.7/site-packages/django/template/loader.py", line 18, in get_template
    engines = _engine_list(using)
  File "/Library/Python/2.7/site-packages/django/template/loader.py", line 72, in _engine_list
    return engines.all() if using is None else [engines[using]]
  File "/Library/Python/2.7/site-packages/django/template/utils.py", line 89, in all
    return [self[alias] for alias in self]
  File "/Library/Python/2.7/site-packages/django/template/utils.py", line 80, in __getitem__
    engine = engine_cls(params)
  File "/Library/Python/2.7/site-packages/django/template/backends/django.py", line 32, in __init__
    self.engine = Engine(self.dirs, self.app_dirs, **options)
  File "/Library/Python/2.7/site-packages/django/template/engine.py", line 35, in __init__
    "app_dirs must not be set when loaders is defined.")
ImproperlyConfigured: app_dirs must not be set when loaders is defined.
[18/Jun/2017 05:00:50] ERROR [django.request:135] Internal Server Error: /
Traceback (most recent call last):
  File "/Library/Python/2.7/site-packages/django/core/handlers/exception.py", line 41, in inner
    response = get_response(request)
  File "/Library/Python/2.7/site-packages/django/utils/deprecation.py", line 140, in __call__
    response = self.get_response(request)
  File "/Library/Python/2.7/site-packages/django/core/handlers/exception.py", line 43, in inner
    response = response_for_exception(request, exc)
  File "/Library/Python/2.7/site-packages/django/core/handlers/exception.py", line 93, in response_for_exception
    response = handle_uncaught_exception(request, get_resolver(get_urlconf()), sys.exc_info())
  File "/Library/Python/2.7/site-packages/django/core/handlers/exception.py", line 143, in handle_uncaught_exception
    return callback(request, **param_dict)
  File "/Library/Python/2.7/site-packages/django/utils/decorators.py", line 149, in _wrapped_view
    response = view_func(request, *args, **kwargs)
  File "/Library/Python/2.7/site-packages/django/views/defaults.py", line 68, in server_error
    template = loader.get_template(template_name)
  File "/Library/Python/2.7/site-packages/django/template/loader.py", line 18, in get_template
    engines = _engine_list(using)
  File "/Library/Python/2.7/site-packages/django/template/loader.py", line 72, in _engine_list
    return engines.all() if using is None else [engines[using]]
  File "/Library/Python/2.7/site-packages/django/template/utils.py", line 89, in all
    return [self[alias] for alias in self]
  File "/Library/Python/2.7/site-packages/django/template/utils.py", line 80, in __getitem__
    engine = engine_cls(params)
  File "/Library/Python/2.7/site-packages/django/template/backends/django.py", line 32, in __init__
    self.engine = Engine(self.dirs, self.app_dirs, **options)
  File "/Library/Python/2.7/site-packages/django/template/engine.py", line 35, in __init__
    "app_dirs must not be set when loaders is defined.")
ImproperlyConfigured: app_dirs must not be set when loaders is defined.
[18/Jun/2017 05:00:50] ERROR [django.request:135] Internal Server Error: /
Traceback (most recent call last):
  File "/Library/Python/2.7/site-packages/django/core/handlers/exception.py", line 41, in inner
    response = get_response(request)
  File "/Library/Python/2.7/site-packages/django/utils/deprecation.py", line 140, in __call__
    response = self.get_response(request)
  File "/Library/Python/2.7/site-packages/django/core/handlers/exception.py", line 43, in inner
    response = response_for_exception(request, exc)
  File "/Library/Python/2.7/site-packages/django/core/handlers/exception.py", line 93, in response_for_exception
    response = handle_uncaught_exception(request, get_resolver(get_urlconf()), sys.exc_info())
  File "/Library/Python/2.7/site-packages/django/core/handlers/exception.py", line 143, in handle_uncaught_exception
    return callback(request, **param_dict)
  File "/Library/Python/2.7/site-packages/django/utils/decorators.py", line 149, in _wrapped_view
    response = view_func(request, *args, **kwargs)
  File "/Library/Python/2.7/site-packages/django/views/defaults.py", line 68, in server_error
    template = loader.get_template(template_name)
  File "/Library/Python/2.7/site-packages/django/template/loader.py", line 18, in get_template
    engines = _engine_list(using)
  File "/Library/Python/2.7/site-packages/django/template/loader.py", line 72, in _engine_list
    return engines.all() if using is None else [engines[using]]
  File "/Library/Python/2.7/site-packages/django/template/utils.py", line 89, in all
    return [self[alias] for alias in self]
  File "/Library/Python/2.7/site-packages/django/template/utils.py", line 80, in __getitem__
    engine = engine_cls(params)
  File "/Library/Python/2.7/site-packages/django/template/backends/django.py", line 32, in __init__
    self.engine = Engine(self.dirs, self.app_dirs, **options)
  File "/Library/Python/2.7/site-packages/django/template/engine.py", line 35, in __init__
    "app_dirs must not be set when loaders is defined.")
ImproperlyConfigured: app_dirs must not be set when loaders is defined.
[18/Jun/2017 05:00:50] ERROR [django.request:135] Internal Server Error: /
Traceback (most recent call last):
  File "/Library/Python/2.7/site-packages/django/core/handlers/exception.py", line 41, in inner
    response = get_response(request)
  File "/Library/Python/2.7/site-packages/django/utils/deprecation.py", line 140, in __call__
    response = self.get_response(request)
  File "/Library/Python/2.7/site-packages/django/core/handlers/exception.py", line 43, in inner
    response = response_for_exception(request, exc)
  File "/Library/Python/2.7/site-packages/django/core/handlers/exception.py", line 93, in response_for_exception
    response = handle_uncaught_exception(request, get_resolver(get_urlconf()), sys.exc_info())
  File "/Library/Python/2.7/site-packages/django/core/handlers/exception.py", line 143, in handle_uncaught_exception
    return callback(request, **param_dict)
  File "/Library/Python/2.7/site-packages/django/utils/decorators.py", line 149, in _wrapped_view
    response = view_func(request, *args, **kwargs)
  File "/Library/Python/2.7/site-packages/django/views/defaults.py", line 68, in server_error
    template = loader.get_template(template_name)
  File "/Library/Python/2.7/site-packages/django/template/loader.py", line 18, in get_template
    engines = _engine_list(using)
  File "/Library/Python/2.7/site-packages/django/template/loader.py", line 72, in _engine_list
    return engines.all() if using is None else [engines[using]]
  File "/Library/Python/2.7/site-packages/django/template/utils.py", line 89, in all
    return [self[alias] for alias in self]
  File "/Library/Python/2.7/site-packages/django/template/utils.py", line 80, in __getitem__
    engine = engine_cls(params)
  File "/Library/Python/2.7/site-packages/django/template/backends/django.py", line 32, in __init__
    self.engine = Engine(self.dirs, self.app_dirs, **options)
  File "/Library/Python/2.7/site-packages/django/template/engine.py", line 35, in __init__
    "app_dirs must not be set when loaders is defined.")
ImproperlyConfigured: app_dirs must not be set when loaders is defined.
[18/Jun/2017 05:00:57] ERROR [django.request:135] Internal Server Error: /
Traceback (most recent call last):
  File "/Library/Python/2.7/site-packages/django/core/handlers/exception.py", line 41, in inner
    response = get_response(request)
  File "/Library/Python/2.7/site-packages/django/core/handlers/base.py", line 217, in _get_response
    response = self.process_exception_by_middleware(e, request)
  File "/Library/Python/2.7/site-packages/django/core/handlers/base.py", line 215, in _get_response
    response = response.render()
  File "/Library/Python/2.7/site-packages/django/template/response.py", line 107, in render
    self.content = self.rendered_content
  File "/Library/Python/2.7/site-packages/django/template/response.py", line 82, in rendered_content
    template = self.resolve_template(self.template_name)
  File "/Library/Python/2.7/site-packages/django/template/response.py", line 64, in resolve_template
    return select_template(template, using=self.using)
  File "/Library/Python/2.7/site-packages/django/template/loader.py", line 48, in select_template
    return engine.get_template(template_name)
  File "/Library/Python/2.7/site-packages/django/template/backends/django.py", line 39, in get_template
    return Template(self.engine.get_template(template_name), self)
  File "/Library/Python/2.7/site-packages/django/template/engine.py", line 162, in get_template
    template, origin = self.find_template(template_name)
  File "/Library/Python/2.7/site-packages/django/template/engine.py", line 132, in find_template
    for loader in self.template_loaders:
  File "/Library/Python/2.7/site-packages/django/utils/functional.py", line 35, in __get__
    res = instance.__dict__[self.name] = self.func(instance)
  File "/Library/Python/2.7/site-packages/django/template/engine.py", line 106, in template_loaders
    return self.get_template_loaders(self.loaders)
  File "/Library/Python/2.7/site-packages/django/template/engine.py", line 111, in get_template_loaders
    loader = self.find_template_loader(template_loader)
  File "/Library/Python/2.7/site-packages/django/template/engine.py", line 125, in find_template_loader
    return loader_class(self, *args)
  File "/Library/Python/2.7/site-packages/django/template/loaders/cached.py", line 24, in __init__
    self.loaders = engine.get_template_loaders(loaders)
  File "/Library/Python/2.7/site-packages/django/template/engine.py", line 111, in get_template_loaders
    loader = self.find_template_loader(template_loader)
  File "/Library/Python/2.7/site-packages/django/template/engine.py", line 124, in find_template_loader
    loader_class = import_string(loader)
  File "/Library/Python/2.7/site-packages/django/utils/module_loading.py", line 20, in import_string
    module = import_module(module_path)
  File "/System/Library/Frameworks/Python.framework/Versions/2.7/lib/python2.7/importlib/__init__.py", line 37, in import_module
    __import__(name)
ImportError: No module named path.to.custom
[18/Jun/2017 05:00:57] ERROR [django.request:135] Internal Server Error: /
Traceback (most recent call last):
  File "/Library/Python/2.7/site-packages/django/core/handlers/exception.py", line 41, in inner
    response = get_response(request)
  File "/Library/Python/2.7/site-packages/django/utils/deprecation.py", line 140, in __call__
    response = self.get_response(request)
  File "/Library/Python/2.7/site-packages/django/core/handlers/exception.py", line 43, in inner
    response = response_for_exception(request, exc)
  File "/Library/Python/2.7/site-packages/django/core/handlers/exception.py", line 93, in response_for_exception
    response = handle_uncaught_exception(request, get_resolver(get_urlconf()), sys.exc_info())
  File "/Library/Python/2.7/site-packages/django/core/handlers/exception.py", line 143, in handle_uncaught_exception
    return callback(request, **param_dict)
  File "/Library/Python/2.7/site-packages/django/utils/decorators.py", line 149, in _wrapped_view
    response = view_func(request, *args, **kwargs)
  File "/Library/Python/2.7/site-packages/django/views/defaults.py", line 68, in server_error
    template = loader.get_template(template_name)
  File "/Library/Python/2.7/site-packages/django/template/loader.py", line 21, in get_template
    return engine.get_template(template_name)
  File "/Library/Python/2.7/site-packages/django/template/backends/django.py", line 39, in get_template
    return Template(self.engine.get_template(template_name), self)
  File "/Library/Python/2.7/site-packages/django/template/engine.py", line 162, in get_template
    template, origin = self.find_template(template_name)
  File "/Library/Python/2.7/site-packages/django/template/engine.py", line 132, in find_template
    for loader in self.template_loaders:
  File "/Library/Python/2.7/site-packages/django/utils/functional.py", line 35, in __get__
    res = instance.__dict__[self.name] = self.func(instance)
  File "/Library/Python/2.7/site-packages/django/template/engine.py", line 106, in template_loaders
    return self.get_template_loaders(self.loaders)
  File "/Library/Python/2.7/site-packages/django/template/engine.py", line 111, in get_template_loaders
    loader = self.find_template_loader(template_loader)
  File "/Library/Python/2.7/site-packages/django/template/engine.py", line 125, in find_template_loader
    return loader_class(self, *args)
  File "/Library/Python/2.7/site-packages/django/template/loaders/cached.py", line 24, in __init__
    self.loaders = engine.get_template_loaders(loaders)
  File "/Library/Python/2.7/site-packages/django/template/engine.py", line 111, in get_template_loaders
    loader = self.find_template_loader(template_loader)
  File "/Library/Python/2.7/site-packages/django/template/engine.py", line 124, in find_template_loader
    loader_class = import_string(loader)
  File "/Library/Python/2.7/site-packages/django/utils/module_loading.py", line 20, in import_string
    module = import_module(module_path)
  File "/System/Library/Frameworks/Python.framework/Versions/2.7/lib/python2.7/importlib/__init__.py", line 37, in import_module
    __import__(name)
ImportError: No module named path.to.custom
[18/Jun/2017 05:00:57] ERROR [django.request:135] Internal Server Error: /
Traceback (most recent call last):
  File "/Library/Python/2.7/site-packages/django/core/handlers/exception.py", line 41, in inner
    response = get_response(request)
  File "/Library/Python/2.7/site-packages/django/utils/deprecation.py", line 140, in __call__
    response = self.get_response(request)
  File "/Library/Python/2.7/site-packages/django/core/handlers/exception.py", line 43, in inner
    response = response_for_exception(request, exc)
  File "/Library/Python/2.7/site-packages/django/core/handlers/exception.py", line 93, in response_for_exception
    response = handle_uncaught_exception(request, get_resolver(get_urlconf()), sys.exc_info())
  File "/Library/Python/2.7/site-packages/django/core/handlers/exception.py", line 143, in handle_uncaught_exception
    return callback(request, **param_dict)
  File "/Library/Python/2.7/site-packages/django/utils/decorators.py", line 149, in _wrapped_view
    response = view_func(request, *args, **kwargs)
  File "/Library/Python/2.7/site-packages/django/views/defaults.py", line 68, in server_error
    template = loader.get_template(template_name)
  File "/Library/Python/2.7/site-packages/django/template/loader.py", line 21, in get_template
    return engine.get_template(template_name)
  File "/Library/Python/2.7/site-packages/django/template/backends/django.py", line 39, in get_template
    return Template(self.engine.get_template(template_name), self)
  File "/Library/Python/2.7/site-packages/django/template/engine.py", line 162, in get_template
    template, origin = self.find_template(template_name)
  File "/Library/Python/2.7/site-packages/django/template/engine.py", line 132, in find_template
    for loader in self.template_loaders:
  File "/Library/Python/2.7/site-packages/django/utils/functional.py", line 35, in __get__
    res = instance.__dict__[self.name] = self.func(instance)
  File "/Library/Python/2.7/site-packages/django/template/engine.py", line 106, in template_loaders
    return self.get_template_loaders(self.loaders)
  File "/Library/Python/2.7/site-packages/django/template/engine.py", line 111, in get_template_loaders
    loader = self.find_template_loader(template_loader)
  File "/Library/Python/2.7/site-packages/django/template/engine.py", line 125, in find_template_loader
    return loader_class(self, *args)
  File "/Library/Python/2.7/site-packages/django/template/loaders/cached.py", line 24, in __init__
    self.loaders = engine.get_template_loaders(loaders)
  File "/Library/Python/2.7/site-packages/django/template/engine.py", line 111, in get_template_loaders
    loader = self.find_template_loader(template_loader)
  File "/Library/Python/2.7/site-packages/django/template/engine.py", line 124, in find_template_loader
    loader_class = import_string(loader)
  File "/Library/Python/2.7/site-packages/django/utils/module_loading.py", line 20, in import_string
    module = import_module(module_path)
  File "/System/Library/Frameworks/Python.framework/Versions/2.7/lib/python2.7/importlib/__init__.py", line 37, in import_module
    __import__(name)
ImportError: No module named path.to.custom
[18/Jun/2017 05:00:57] ERROR [django.request:135] Internal Server Error: /
Traceback (most recent call last):
  File "/Library/Python/2.7/site-packages/django/core/handlers/exception.py", line 41, in inner
    response = get_response(request)
  File "/Library/Python/2.7/site-packages/django/utils/deprecation.py", line 140, in __call__
    response = self.get_response(request)
  File "/Library/Python/2.7/site-packages/django/core/handlers/exception.py", line 43, in inner
    response = response_for_exception(request, exc)
  File "/Library/Python/2.7/site-packages/django/core/handlers/exception.py", line 93, in response_for_exception
    response = handle_uncaught_exception(request, get_resolver(get_urlconf()), sys.exc_info())
  File "/Library/Python/2.7/site-packages/django/core/handlers/exception.py", line 143, in handle_uncaught_exception
    return callback(request, **param_dict)
  File "/Library/Python/2.7/site-packages/django/utils/decorators.py", line 149, in _wrapped_view
    response = view_func(request, *args, **kwargs)
  File "/Library/Python/2.7/site-packages/django/views/defaults.py", line 68, in server_error
    template = loader.get_template(template_name)
  File "/Library/Python/2.7/site-packages/django/template/loader.py", line 21, in get_template
    return engine.get_template(template_name)
  File "/Library/Python/2.7/site-packages/django/template/backends/django.py", line 39, in get_template
    return Template(self.engine.get_template(template_name), self)
  File "/Library/Python/2.7/site-packages/django/template/engine.py", line 162, in get_template
    template, origin = self.find_template(template_name)
  File "/Library/Python/2.7/site-packages/django/template/engine.py", line 132, in find_template
    for loader in self.template_loaders:
  File "/Library/Python/2.7/site-packages/django/utils/functional.py", line 35, in __get__
    res = instance.__dict__[self.name] = self.func(instance)
  File "/Library/Python/2.7/site-packages/django/template/engine.py", line 106, in template_loaders
    return self.get_template_loaders(self.loaders)
  File "/Library/Python/2.7/site-packages/django/template/engine.py", line 111, in get_template_loaders
    loader = self.find_template_loader(template_loader)
  File "/Library/Python/2.7/site-packages/django/template/engine.py", line 125, in find_template_loader
    return loader_class(self, *args)
  File "/Library/Python/2.7/site-packages/django/template/loaders/cached.py", line 24, in __init__
    self.loaders = engine.get_template_loaders(loaders)
  File "/Library/Python/2.7/site-packages/django/template/engine.py", line 111, in get_template_loaders
    loader = self.find_template_loader(template_loader)
  File "/Library/Python/2.7/site-packages/django/template/engine.py", line 124, in find_template_loader
    loader_class = import_string(loader)
  File "/Library/Python/2.7/site-packages/django/utils/module_loading.py", line 20, in import_string
    module = import_module(module_path)
  File "/System/Library/Frameworks/Python.framework/Versions/2.7/lib/python2.7/importlib/__init__.py", line 37, in import_module
    __import__(name)
ImportError: No module named path.to.custom
[18/Jun/2017 05:00:57] ERROR [django.request:135] Internal Server Error: /
Traceback (most recent call last):
  File "/Library/Python/2.7/site-packages/django/core/handlers/exception.py", line 41, in inner
    response = get_response(request)
  File "/Library/Python/2.7/site-packages/django/utils/deprecation.py", line 140, in __call__
    response = self.get_response(request)
  File "/Library/Python/2.7/site-packages/django/core/handlers/exception.py", line 43, in inner
    response = response_for_exception(request, exc)
  File "/Library/Python/2.7/site-packages/django/core/handlers/exception.py", line 93, in response_for_exception
    response = handle_uncaught_exception(request, get_resolver(get_urlconf()), sys.exc_info())
  File "/Library/Python/2.7/site-packages/django/core/handlers/exception.py", line 143, in handle_uncaught_exception
    return callback(request, **param_dict)
  File "/Library/Python/2.7/site-packages/django/utils/decorators.py", line 149, in _wrapped_view
    response = view_func(request, *args, **kwargs)
  File "/Library/Python/2.7/site-packages/django/views/defaults.py", line 68, in server_error
    template = loader.get_template(template_name)
  File "/Library/Python/2.7/site-packages/django/template/loader.py", line 21, in get_template
    return engine.get_template(template_name)
  File "/Library/Python/2.7/site-packages/django/template/backends/django.py", line 39, in get_template
    return Template(self.engine.get_template(template_name), self)
  File "/Library/Python/2.7/site-packages/django/template/engine.py", line 162, in get_template
    template, origin = self.find_template(template_name)
  File "/Library/Python/2.7/site-packages/django/template/engine.py", line 132, in find_template
    for loader in self.template_loaders:
  File "/Library/Python/2.7/site-packages/django/utils/functional.py", line 35, in __get__
    res = instance.__dict__[self.name] = self.func(instance)
  File "/Library/Python/2.7/site-packages/django/template/engine.py", line 106, in template_loaders
    return self.get_template_loaders(self.loaders)
  File "/Library/Python/2.7/site-packages/django/template/engine.py", line 111, in get_template_loaders
    loader = self.find_template_loader(template_loader)
  File "/Library/Python/2.7/site-packages/django/template/engine.py", line 125, in find_template_loader
    return loader_class(self, *args)
  File "/Library/Python/2.7/site-packages/django/template/loaders/cached.py", line 24, in __init__
    self.loaders = engine.get_template_loaders(loaders)
  File "/Library/Python/2.7/site-packages/django/template/engine.py", line 111, in get_template_loaders
    loader = self.find_template_loader(template_loader)
  File "/Library/Python/2.7/site-packages/django/template/engine.py", line 124, in find_template_loader
    loader_class = import_string(loader)
  File "/Library/Python/2.7/site-packages/django/utils/module_loading.py", line 20, in import_string
    module = import_module(module_path)
  File "/System/Library/Frameworks/Python.framework/Versions/2.7/lib/python2.7/importlib/__init__.py", line 37, in import_module
    __import__(name)
ImportError: No module named path.to.custom
[18/Jun/2017 05:00:57] ERROR [django.request:135] Internal Server Error: /
Traceback (most recent call last):
  File "/Library/Python/2.7/site-packages/django/core/handlers/exception.py", line 41, in inner
    response = get_response(request)
  File "/Library/Python/2.7/site-packages/django/utils/deprecation.py", line 140, in __call__
    response = self.get_response(request)
  File "/Library/Python/2.7/site-packages/django/core/handlers/exception.py", line 43, in inner
    response = response_for_exception(request, exc)
  File "/Library/Python/2.7/site-packages/django/core/handlers/exception.py", line 93, in response_for_exception
    response = handle_uncaught_exception(request, get_resolver(get_urlconf()), sys.exc_info())
  File "/Library/Python/2.7/site-packages/django/core/handlers/exception.py", line 143, in handle_uncaught_exception
    return callback(request, **param_dict)
  File "/Library/Python/2.7/site-packages/django/utils/decorators.py", line 149, in _wrapped_view
    response = view_func(request, *args, **kwargs)
  File "/Library/Python/2.7/site-packages/django/views/defaults.py", line 68, in server_error
    template = loader.get_template(template_name)
  File "/Library/Python/2.7/site-packages/django/template/loader.py", line 21, in get_template
    return engine.get_template(template_name)
  File "/Library/Python/2.7/site-packages/django/template/backends/django.py", line 39, in get_template
    return Template(self.engine.get_template(template_name), self)
  File "/Library/Python/2.7/site-packages/django/template/engine.py", line 162, in get_template
    template, origin = self.find_template(template_name)
  File "/Library/Python/2.7/site-packages/django/template/engine.py", line 132, in find_template
    for loader in self.template_loaders:
  File "/Library/Python/2.7/site-packages/django/utils/functional.py", line 35, in __get__
    res = instance.__dict__[self.name] = self.func(instance)
  File "/Library/Python/2.7/site-packages/django/template/engine.py", line 106, in template_loaders
    return self.get_template_loaders(self.loaders)
  File "/Library/Python/2.7/site-packages/django/template/engine.py", line 111, in get_template_loaders
    loader = self.find_template_loader(template_loader)
  File "/Library/Python/2.7/site-packages/django/template/engine.py", line 125, in find_template_loader
    return loader_class(self, *args)
  File "/Library/Python/2.7/site-packages/django/template/loaders/cached.py", line 24, in __init__
    self.loaders = engine.get_template_loaders(loaders)
  File "/Library/Python/2.7/site-packages/django/template/engine.py", line 111, in get_template_loaders
    loader = self.find_template_loader(template_loader)
  File "/Library/Python/2.7/site-packages/django/template/engine.py", line 124, in find_template_loader
    loader_class = import_string(loader)
  File "/Library/Python/2.7/site-packages/django/utils/module_loading.py", line 20, in import_string
    module = import_module(module_path)
  File "/System/Library/Frameworks/Python.framework/Versions/2.7/lib/python2.7/importlib/__init__.py", line 37, in import_module
    __import__(name)
ImportError: No module named path.to.custom
[18/Jun/2017 05:00:57] ERROR [django.request:135] Internal Server Error: /
Traceback (most recent call last):
  File "/Library/Python/2.7/site-packages/django/core/handlers/exception.py", line 41, in inner
    response = get_response(request)
  File "/Library/Python/2.7/site-packages/django/utils/deprecation.py", line 140, in __call__
    response = self.get_response(request)
  File "/Library/Python/2.7/site-packages/django/core/handlers/exception.py", line 43, in inner
    response = response_for_exception(request, exc)
  File "/Library/Python/2.7/site-packages/django/core/handlers/exception.py", line 93, in response_for_exception
    response = handle_uncaught_exception(request, get_resolver(get_urlconf()), sys.exc_info())
  File "/Library/Python/2.7/site-packages/django/core/handlers/exception.py", line 143, in handle_uncaught_exception
    return callback(request, **param_dict)
  File "/Library/Python/2.7/site-packages/django/utils/decorators.py", line 149, in _wrapped_view
    response = view_func(request, *args, **kwargs)
  File "/Library/Python/2.7/site-packages/django/views/defaults.py", line 68, in server_error
    template = loader.get_template(template_name)
  File "/Library/Python/2.7/site-packages/django/template/loader.py", line 21, in get_template
    return engine.get_template(template_name)
  File "/Library/Python/2.7/site-packages/django/template/backends/django.py", line 39, in get_template
    return Template(self.engine.get_template(template_name), self)
  File "/Library/Python/2.7/site-packages/django/template/engine.py", line 162, in get_template
    template, origin = self.find_template(template_name)
  File "/Library/Python/2.7/site-packages/django/template/engine.py", line 132, in find_template
    for loader in self.template_loaders:
  File "/Library/Python/2.7/site-packages/django/utils/functional.py", line 35, in __get__
    res = instance.__dict__[self.name] = self.func(instance)
  File "/Library/Python/2.7/site-packages/django/template/engine.py", line 106, in template_loaders
    return self.get_template_loaders(self.loaders)
  File "/Library/Python/2.7/site-packages/django/template/engine.py", line 111, in get_template_loaders
    loader = self.find_template_loader(template_loader)
  File "/Library/Python/2.7/site-packages/django/template/engine.py", line 125, in find_template_loader
    return loader_class(self, *args)
  File "/Library/Python/2.7/site-packages/django/template/loaders/cached.py", line 24, in __init__
    self.loaders = engine.get_template_loaders(loaders)
  File "/Library/Python/2.7/site-packages/django/template/engine.py", line 111, in get_template_loaders
    loader = self.find_template_loader(template_loader)
  File "/Library/Python/2.7/site-packages/django/template/engine.py", line 124, in find_template_loader
    loader_class = import_string(loader)
  File "/Library/Python/2.7/site-packages/django/utils/module_loading.py", line 20, in import_string
    module = import_module(module_path)
  File "/System/Library/Frameworks/Python.framework/Versions/2.7/lib/python2.7/importlib/__init__.py", line 37, in import_module
    __import__(name)
ImportError: No module named path.to.custom
[18/Jun/2017 05:00:57] ERROR [django.request:135] Internal Server Error: /
Traceback (most recent call last):
  File "/Library/Python/2.7/site-packages/django/core/handlers/exception.py", line 41, in inner
    response = get_response(request)
  File "/Library/Python/2.7/site-packages/django/utils/deprecation.py", line 140, in __call__
    response = self.get_response(request)
  File "/Library/Python/2.7/site-packages/django/core/handlers/exception.py", line 43, in inner
    response = response_for_exception(request, exc)
  File "/Library/Python/2.7/site-packages/django/core/handlers/exception.py", line 93, in response_for_exception
    response = handle_uncaught_exception(request, get_resolver(get_urlconf()), sys.exc_info())
  File "/Library/Python/2.7/site-packages/django/core/handlers/exception.py", line 143, in handle_uncaught_exception
    return callback(request, **param_dict)
  File "/Library/Python/2.7/site-packages/django/utils/decorators.py", line 149, in _wrapped_view
    response = view_func(request, *args, **kwargs)
  File "/Library/Python/2.7/site-packages/django/views/defaults.py", line 68, in server_error
    template = loader.get_template(template_name)
  File "/Library/Python/2.7/site-packages/django/template/loader.py", line 21, in get_template
    return engine.get_template(template_name)
  File "/Library/Python/2.7/site-packages/django/template/backends/django.py", line 39, in get_template
    return Template(self.engine.get_template(template_name), self)
  File "/Library/Python/2.7/site-packages/django/template/engine.py", line 162, in get_template
    template, origin = self.find_template(template_name)
  File "/Library/Python/2.7/site-packages/django/template/engine.py", line 132, in find_template
    for loader in self.template_loaders:
  File "/Library/Python/2.7/site-packages/django/utils/functional.py", line 35, in __get__
    res = instance.__dict__[self.name] = self.func(instance)
  File "/Library/Python/2.7/site-packages/django/template/engine.py", line 106, in template_loaders
    return self.get_template_loaders(self.loaders)
  File "/Library/Python/2.7/site-packages/django/template/engine.py", line 111, in get_template_loaders
    loader = self.find_template_loader(template_loader)
  File "/Library/Python/2.7/site-packages/django/template/engine.py", line 125, in find_template_loader
    return loader_class(self, *args)
  File "/Library/Python/2.7/site-packages/django/template/loaders/cached.py", line 24, in __init__
    self.loaders = engine.get_template_loaders(loaders)
  File "/Library/Python/2.7/site-packages/django/template/engine.py", line 111, in get_template_loaders
    loader = self.find_template_loader(template_loader)
  File "/Library/Python/2.7/site-packages/django/template/engine.py", line 124, in find_template_loader
    loader_class = import_string(loader)
  File "/Library/Python/2.7/site-packages/django/utils/module_loading.py", line 20, in import_string
    module = import_module(module_path)
  File "/System/Library/Frameworks/Python.framework/Versions/2.7/lib/python2.7/importlib/__init__.py", line 37, in import_module
    __import__(name)
ImportError: No module named path.to.custom
[18/Jun/2017 05:01:06] ERROR [django.request:135] Internal Server Error: /
Traceback (most recent call last):
  File "/Library/Python/2.7/site-packages/django/core/handlers/exception.py", line 41, in inner
    response = get_response(request)
  File "/Library/Python/2.7/site-packages/django/core/handlers/base.py", line 217, in _get_response
    response = self.process_exception_by_middleware(e, request)
  File "/Library/Python/2.7/site-packages/django/core/handlers/base.py", line 215, in _get_response
    response = response.render()
  File "/Library/Python/2.7/site-packages/django/template/response.py", line 107, in render
    self.content = self.rendered_content
  File "/Library/Python/2.7/site-packages/django/template/response.py", line 82, in rendered_content
    template = self.resolve_template(self.template_name)
  File "/Library/Python/2.7/site-packages/django/template/response.py", line 64, in resolve_template
    return select_template(template, using=self.using)
  File "/Library/Python/2.7/site-packages/django/template/loader.py", line 48, in select_template
    return engine.get_template(template_name)
  File "/Library/Python/2.7/site-packages/django/template/backends/django.py", line 39, in get_template
    return Template(self.engine.get_template(template_name), self)
  File "/Library/Python/2.7/site-packages/django/template/engine.py", line 162, in get_template
    template, origin = self.find_template(template_name)
  File "/Library/Python/2.7/site-packages/django/template/engine.py", line 132, in find_template
    for loader in self.template_loaders:
  File "/Library/Python/2.7/site-packages/django/utils/functional.py", line 35, in __get__
    res = instance.__dict__[self.name] = self.func(instance)
  File "/Library/Python/2.7/site-packages/django/template/engine.py", line 106, in template_loaders
    return self.get_template_loaders(self.loaders)
  File "/Library/Python/2.7/site-packages/django/template/engine.py", line 111, in get_template_loaders
    loader = self.find_template_loader(template_loader)
  File "/Library/Python/2.7/site-packages/django/template/engine.py", line 125, in find_template_loader
    return loader_class(self, *args)
  File "/Library/Python/2.7/site-packages/django/template/loaders/cached.py", line 24, in __init__
    self.loaders = engine.get_template_loaders(loaders)
  File "/Library/Python/2.7/site-packages/django/template/engine.py", line 111, in get_template_loaders
    loader = self.find_template_loader(template_loader)
  File "/Library/Python/2.7/site-packages/django/template/engine.py", line 124, in find_template_loader
    loader_class = import_string(loader)
  File "/Library/Python/2.7/site-packages/django/utils/module_loading.py", line 20, in import_string
    module = import_module(module_path)
  File "/System/Library/Frameworks/Python.framework/Versions/2.7/lib/python2.7/importlib/__init__.py", line 37, in import_module
    __import__(name)
ImportError: No module named path.to.custom
[18/Jun/2017 05:01:06] ERROR [django.request:135] Internal Server Error: /
Traceback (most recent call last):
  File "/Library/Python/2.7/site-packages/django/core/handlers/exception.py", line 41, in inner
    response = get_response(request)
  File "/Library/Python/2.7/site-packages/django/utils/deprecation.py", line 140, in __call__
    response = self.get_response(request)
  File "/Library/Python/2.7/site-packages/django/core/handlers/exception.py", line 43, in inner
    response = response_for_exception(request, exc)
  File "/Library/Python/2.7/site-packages/django/core/handlers/exception.py", line 93, in response_for_exception
    response = handle_uncaught_exception(request, get_resolver(get_urlconf()), sys.exc_info())
  File "/Library/Python/2.7/site-packages/django/core/handlers/exception.py", line 143, in handle_uncaught_exception
    return callback(request, **param_dict)
  File "/Library/Python/2.7/site-packages/django/utils/decorators.py", line 149, in _wrapped_view
    response = view_func(request, *args, **kwargs)
  File "/Library/Python/2.7/site-packages/django/views/defaults.py", line 68, in server_error
    template = loader.get_template(template_name)
  File "/Library/Python/2.7/site-packages/django/template/loader.py", line 21, in get_template
    return engine.get_template(template_name)
  File "/Library/Python/2.7/site-packages/django/template/backends/django.py", line 39, in get_template
    return Template(self.engine.get_template(template_name), self)
  File "/Library/Python/2.7/site-packages/django/template/engine.py", line 162, in get_template
    template, origin = self.find_template(template_name)
  File "/Library/Python/2.7/site-packages/django/template/engine.py", line 132, in find_template
    for loader in self.template_loaders:
  File "/Library/Python/2.7/site-packages/django/utils/functional.py", line 35, in __get__
    res = instance.__dict__[self.name] = self.func(instance)
  File "/Library/Python/2.7/site-packages/django/template/engine.py", line 106, in template_loaders
    return self.get_template_loaders(self.loaders)
  File "/Library/Python/2.7/site-packages/django/template/engine.py", line 111, in get_template_loaders
    loader = self.find_template_loader(template_loader)
  File "/Library/Python/2.7/site-packages/django/template/engine.py", line 125, in find_template_loader
    return loader_class(self, *args)
  File "/Library/Python/2.7/site-packages/django/template/loaders/cached.py", line 24, in __init__
    self.loaders = engine.get_template_loaders(loaders)
  File "/Library/Python/2.7/site-packages/django/template/engine.py", line 111, in get_template_loaders
    loader = self.find_template_loader(template_loader)
  File "/Library/Python/2.7/site-packages/django/template/engine.py", line 124, in find_template_loader
    loader_class = import_string(loader)
  File "/Library/Python/2.7/site-packages/django/utils/module_loading.py", line 20, in import_string
    module = import_module(module_path)
  File "/System/Library/Frameworks/Python.framework/Versions/2.7/lib/python2.7/importlib/__init__.py", line 37, in import_module
    __import__(name)
ImportError: No module named path.to.custom
[18/Jun/2017 05:01:06] ERROR [django.request:135] Internal Server Error: /
Traceback (most recent call last):
  File "/Library/Python/2.7/site-packages/django/core/handlers/exception.py", line 41, in inner
    response = get_response(request)
  File "/Library/Python/2.7/site-packages/django/utils/deprecation.py", line 140, in __call__
    response = self.get_response(request)
  File "/Library/Python/2.7/site-packages/django/core/handlers/exception.py", line 43, in inner
    response = response_for_exception(request, exc)
  File "/Library/Python/2.7/site-packages/django/core/handlers/exception.py", line 93, in response_for_exception
    response = handle_uncaught_exception(request, get_resolver(get_urlconf()), sys.exc_info())
  File "/Library/Python/2.7/site-packages/django/core/handlers/exception.py", line 143, in handle_uncaught_exception
    return callback(request, **param_dict)
  File "/Library/Python/2.7/site-packages/django/utils/decorators.py", line 149, in _wrapped_view
    response = view_func(request, *args, **kwargs)
  File "/Library/Python/2.7/site-packages/django/views/defaults.py", line 68, in server_error
    template = loader.get_template(template_name)
  File "/Library/Python/2.7/site-packages/django/template/loader.py", line 21, in get_template
    return engine.get_template(template_name)
  File "/Library/Python/2.7/site-packages/django/template/backends/django.py", line 39, in get_template
    return Template(self.engine.get_template(template_name), self)
  File "/Library/Python/2.7/site-packages/django/template/engine.py", line 162, in get_template
    template, origin = self.find_template(template_name)
  File "/Library/Python/2.7/site-packages/django/template/engine.py", line 132, in find_template
    for loader in self.template_loaders:
  File "/Library/Python/2.7/site-packages/django/utils/functional.py", line 35, in __get__
    res = instance.__dict__[self.name] = self.func(instance)
  File "/Library/Python/2.7/site-packages/django/template/engine.py", line 106, in template_loaders
    return self.get_template_loaders(self.loaders)
  File "/Library/Python/2.7/site-packages/django/template/engine.py", line 111, in get_template_loaders
    loader = self.find_template_loader(template_loader)
  File "/Library/Python/2.7/site-packages/django/template/engine.py", line 125, in find_template_loader
    return loader_class(self, *args)
  File "/Library/Python/2.7/site-packages/django/template/loaders/cached.py", line 24, in __init__
    self.loaders = engine.get_template_loaders(loaders)
  File "/Library/Python/2.7/site-packages/django/template/engine.py", line 111, in get_template_loaders
    loader = self.find_template_loader(template_loader)
  File "/Library/Python/2.7/site-packages/django/template/engine.py", line 124, in find_template_loader
    loader_class = import_string(loader)
  File "/Library/Python/2.7/site-packages/django/utils/module_loading.py", line 20, in import_string
    module = import_module(module_path)
  File "/System/Library/Frameworks/Python.framework/Versions/2.7/lib/python2.7/importlib/__init__.py", line 37, in import_module
    __import__(name)
ImportError: No module named path.to.custom
[18/Jun/2017 05:01:06] ERROR [django.request:135] Internal Server Error: /
Traceback (most recent call last):
  File "/Library/Python/2.7/site-packages/django/core/handlers/exception.py", line 41, in inner
    response = get_response(request)
  File "/Library/Python/2.7/site-packages/django/utils/deprecation.py", line 140, in __call__
    response = self.get_response(request)
  File "/Library/Python/2.7/site-packages/django/core/handlers/exception.py", line 43, in inner
    response = response_for_exception(request, exc)
  File "/Library/Python/2.7/site-packages/django/core/handlers/exception.py", line 93, in response_for_exception
    response = handle_uncaught_exception(request, get_resolver(get_urlconf()), sys.exc_info())
  File "/Library/Python/2.7/site-packages/django/core/handlers/exception.py", line 143, in handle_uncaught_exception
    return callback(request, **param_dict)
  File "/Library/Python/2.7/site-packages/django/utils/decorators.py", line 149, in _wrapped_view
    response = view_func(request, *args, **kwargs)
  File "/Library/Python/2.7/site-packages/django/views/defaults.py", line 68, in server_error
    template = loader.get_template(template_name)
  File "/Library/Python/2.7/site-packages/django/template/loader.py", line 21, in get_template
    return engine.get_template(template_name)
  File "/Library/Python/2.7/site-packages/django/template/backends/django.py", line 39, in get_template
    return Template(self.engine.get_template(template_name), self)
  File "/Library/Python/2.7/site-packages/django/template/engine.py", line 162, in get_template
    template, origin = self.find_template(template_name)
  File "/Library/Python/2.7/site-packages/django/template/engine.py", line 132, in find_template
    for loader in self.template_loaders:
  File "/Library/Python/2.7/site-packages/django/utils/functional.py", line 35, in __get__
    res = instance.__dict__[self.name] = self.func(instance)
  File "/Library/Python/2.7/site-packages/django/template/engine.py", line 106, in template_loaders
    return self.get_template_loaders(self.loaders)
  File "/Library/Python/2.7/site-packages/django/template/engine.py", line 111, in get_template_loaders
    loader = self.find_template_loader(template_loader)
  File "/Library/Python/2.7/site-packages/django/template/engine.py", line 125, in find_template_loader
    return loader_class(self, *args)
  File "/Library/Python/2.7/site-packages/django/template/loaders/cached.py", line 24, in __init__
    self.loaders = engine.get_template_loaders(loaders)
  File "/Library/Python/2.7/site-packages/django/template/engine.py", line 111, in get_template_loaders
    loader = self.find_template_loader(template_loader)
  File "/Library/Python/2.7/site-packages/django/template/engine.py", line 124, in find_template_loader
    loader_class = import_string(loader)
  File "/Library/Python/2.7/site-packages/django/utils/module_loading.py", line 20, in import_string
    module = import_module(module_path)
  File "/System/Library/Frameworks/Python.framework/Versions/2.7/lib/python2.7/importlib/__init__.py", line 37, in import_module
    __import__(name)
ImportError: No module named path.to.custom
[18/Jun/2017 05:01:06] ERROR [django.request:135] Internal Server Error: /
Traceback (most recent call last):
  File "/Library/Python/2.7/site-packages/django/core/handlers/exception.py", line 41, in inner
    response = get_response(request)
  File "/Library/Python/2.7/site-packages/django/utils/deprecation.py", line 140, in __call__
    response = self.get_response(request)
  File "/Library/Python/2.7/site-packages/django/core/handlers/exception.py", line 43, in inner
    response = response_for_exception(request, exc)
  File "/Library/Python/2.7/site-packages/django/core/handlers/exception.py", line 93, in response_for_exception
    response = handle_uncaught_exception(request, get_resolver(get_urlconf()), sys.exc_info())
  File "/Library/Python/2.7/site-packages/django/core/handlers/exception.py", line 143, in handle_uncaught_exception
    return callback(request, **param_dict)
  File "/Library/Python/2.7/site-packages/django/utils/decorators.py", line 149, in _wrapped_view
    response = view_func(request, *args, **kwargs)
  File "/Library/Python/2.7/site-packages/django/views/defaults.py", line 68, in server_error
    template = loader.get_template(template_name)
  File "/Library/Python/2.7/site-packages/django/template/loader.py", line 21, in get_template
    return engine.get_template(template_name)
  File "/Library/Python/2.7/site-packages/django/template/backends/django.py", line 39, in get_template
    return Template(self.engine.get_template(template_name), self)
  File "/Library/Python/2.7/site-packages/django/template/engine.py", line 162, in get_template
    template, origin = self.find_template(template_name)
  File "/Library/Python/2.7/site-packages/django/template/engine.py", line 132, in find_template
    for loader in self.template_loaders:
  File "/Library/Python/2.7/site-packages/django/utils/functional.py", line 35, in __get__
    res = instance.__dict__[self.name] = self.func(instance)
  File "/Library/Python/2.7/site-packages/django/template/engine.py", line 106, in template_loaders
    return self.get_template_loaders(self.loaders)
  File "/Library/Python/2.7/site-packages/django/template/engine.py", line 111, in get_template_loaders
    loader = self.find_template_loader(template_loader)
  File "/Library/Python/2.7/site-packages/django/template/engine.py", line 125, in find_template_loader
    return loader_class(self, *args)
  File "/Library/Python/2.7/site-packages/django/template/loaders/cached.py", line 24, in __init__
    self.loaders = engine.get_template_loaders(loaders)
  File "/Library/Python/2.7/site-packages/django/template/engine.py", line 111, in get_template_loaders
    loader = self.find_template_loader(template_loader)
  File "/Library/Python/2.7/site-packages/django/template/engine.py", line 124, in find_template_loader
    loader_class = import_string(loader)
  File "/Library/Python/2.7/site-packages/django/utils/module_loading.py", line 20, in import_string
    module = import_module(module_path)
  File "/System/Library/Frameworks/Python.framework/Versions/2.7/lib/python2.7/importlib/__init__.py", line 37, in import_module
    __import__(name)
ImportError: No module named path.to.custom
[18/Jun/2017 05:01:06] ERROR [django.request:135] Internal Server Error: /
Traceback (most recent call last):
  File "/Library/Python/2.7/site-packages/django/core/handlers/exception.py", line 41, in inner
    response = get_response(request)
  File "/Library/Python/2.7/site-packages/django/utils/deprecation.py", line 140, in __call__
    response = self.get_response(request)
  File "/Library/Python/2.7/site-packages/django/core/handlers/exception.py", line 43, in inner
    response = response_for_exception(request, exc)
  File "/Library/Python/2.7/site-packages/django/core/handlers/exception.py", line 93, in response_for_exception
    response = handle_uncaught_exception(request, get_resolver(get_urlconf()), sys.exc_info())
  File "/Library/Python/2.7/site-packages/django/core/handlers/exception.py", line 143, in handle_uncaught_exception
    return callback(request, **param_dict)
  File "/Library/Python/2.7/site-packages/django/utils/decorators.py", line 149, in _wrapped_view
    response = view_func(request, *args, **kwargs)
  File "/Library/Python/2.7/site-packages/django/views/defaults.py", line 68, in server_error
    template = loader.get_template(template_name)
  File "/Library/Python/2.7/site-packages/django/template/loader.py", line 21, in get_template
    return engine.get_template(template_name)
  File "/Library/Python/2.7/site-packages/django/template/backends/django.py", line 39, in get_template
    return Template(self.engine.get_template(template_name), self)
  File "/Library/Python/2.7/site-packages/django/template/engine.py", line 162, in get_template
    template, origin = self.find_template(template_name)
  File "/Library/Python/2.7/site-packages/django/template/engine.py", line 132, in find_template
    for loader in self.template_loaders:
  File "/Library/Python/2.7/site-packages/django/utils/functional.py", line 35, in __get__
    res = instance.__dict__[self.name] = self.func(instance)
  File "/Library/Python/2.7/site-packages/django/template/engine.py", line 106, in template_loaders
    return self.get_template_loaders(self.loaders)
  File "/Library/Python/2.7/site-packages/django/template/engine.py", line 111, in get_template_loaders
    loader = self.find_template_loader(template_loader)
  File "/Library/Python/2.7/site-packages/django/template/engine.py", line 125, in find_template_loader
    return loader_class(self, *args)
  File "/Library/Python/2.7/site-packages/django/template/loaders/cached.py", line 24, in __init__
    self.loaders = engine.get_template_loaders(loaders)
  File "/Library/Python/2.7/site-packages/django/template/engine.py", line 111, in get_template_loaders
    loader = self.find_template_loader(template_loader)
  File "/Library/Python/2.7/site-packages/django/template/engine.py", line 124, in find_template_loader
    loader_class = import_string(loader)
  File "/Library/Python/2.7/site-packages/django/utils/module_loading.py", line 20, in import_string
    module = import_module(module_path)
  File "/System/Library/Frameworks/Python.framework/Versions/2.7/lib/python2.7/importlib/__init__.py", line 37, in import_module
    __import__(name)
ImportError: No module named path.to.custom
[18/Jun/2017 05:01:06] ERROR [django.request:135] Internal Server Error: /
Traceback (most recent call last):
  File "/Library/Python/2.7/site-packages/django/core/handlers/exception.py", line 41, in inner
    response = get_response(request)
  File "/Library/Python/2.7/site-packages/django/utils/deprecation.py", line 140, in __call__
    response = self.get_response(request)
  File "/Library/Python/2.7/site-packages/django/core/handlers/exception.py", line 43, in inner
    response = response_for_exception(request, exc)
  File "/Library/Python/2.7/site-packages/django/core/handlers/exception.py", line 93, in response_for_exception
    response = handle_uncaught_exception(request, get_resolver(get_urlconf()), sys.exc_info())
  File "/Library/Python/2.7/site-packages/django/core/handlers/exception.py", line 143, in handle_uncaught_exception
    return callback(request, **param_dict)
  File "/Library/Python/2.7/site-packages/django/utils/decorators.py", line 149, in _wrapped_view
    response = view_func(request, *args, **kwargs)
  File "/Library/Python/2.7/site-packages/django/views/defaults.py", line 68, in server_error
    template = loader.get_template(template_name)
  File "/Library/Python/2.7/site-packages/django/template/loader.py", line 21, in get_template
    return engine.get_template(template_name)
  File "/Library/Python/2.7/site-packages/django/template/backends/django.py", line 39, in get_template
    return Template(self.engine.get_template(template_name), self)
  File "/Library/Python/2.7/site-packages/django/template/engine.py", line 162, in get_template
    template, origin = self.find_template(template_name)
  File "/Library/Python/2.7/site-packages/django/template/engine.py", line 132, in find_template
    for loader in self.template_loaders:
  File "/Library/Python/2.7/site-packages/django/utils/functional.py", line 35, in __get__
    res = instance.__dict__[self.name] = self.func(instance)
  File "/Library/Python/2.7/site-packages/django/template/engine.py", line 106, in template_loaders
    return self.get_template_loaders(self.loaders)
  File "/Library/Python/2.7/site-packages/django/template/engine.py", line 111, in get_template_loaders
    loader = self.find_template_loader(template_loader)
  File "/Library/Python/2.7/site-packages/django/template/engine.py", line 125, in find_template_loader
    return loader_class(self, *args)
  File "/Library/Python/2.7/site-packages/django/template/loaders/cached.py", line 24, in __init__
    self.loaders = engine.get_template_loaders(loaders)
  File "/Library/Python/2.7/site-packages/django/template/engine.py", line 111, in get_template_loaders
    loader = self.find_template_loader(template_loader)
  File "/Library/Python/2.7/site-packages/django/template/engine.py", line 124, in find_template_loader
    loader_class = import_string(loader)
  File "/Library/Python/2.7/site-packages/django/utils/module_loading.py", line 20, in import_string
    module = import_module(module_path)
  File "/System/Library/Frameworks/Python.framework/Versions/2.7/lib/python2.7/importlib/__init__.py", line 37, in import_module
    __import__(name)
ImportError: No module named path.to.custom
[18/Jun/2017 05:01:06] ERROR [django.request:135] Internal Server Error: /
Traceback (most recent call last):
  File "/Library/Python/2.7/site-packages/django/core/handlers/exception.py", line 41, in inner
    response = get_response(request)
  File "/Library/Python/2.7/site-packages/django/utils/deprecation.py", line 140, in __call__
    response = self.get_response(request)
  File "/Library/Python/2.7/site-packages/django/core/handlers/exception.py", line 43, in inner
    response = response_for_exception(request, exc)
  File "/Library/Python/2.7/site-packages/django/core/handlers/exception.py", line 93, in response_for_exception
    response = handle_uncaught_exception(request, get_resolver(get_urlconf()), sys.exc_info())
  File "/Library/Python/2.7/site-packages/django/core/handlers/exception.py", line 143, in handle_uncaught_exception
    return callback(request, **param_dict)
  File "/Library/Python/2.7/site-packages/django/utils/decorators.py", line 149, in _wrapped_view
    response = view_func(request, *args, **kwargs)
  File "/Library/Python/2.7/site-packages/django/views/defaults.py", line 68, in server_error
    template = loader.get_template(template_name)
  File "/Library/Python/2.7/site-packages/django/template/loader.py", line 21, in get_template
    return engine.get_template(template_name)
  File "/Library/Python/2.7/site-packages/django/template/backends/django.py", line 39, in get_template
    return Template(self.engine.get_template(template_name), self)
  File "/Library/Python/2.7/site-packages/django/template/engine.py", line 162, in get_template
    template, origin = self.find_template(template_name)
  File "/Library/Python/2.7/site-packages/django/template/engine.py", line 132, in find_template
    for loader in self.template_loaders:
  File "/Library/Python/2.7/site-packages/django/utils/functional.py", line 35, in __get__
    res = instance.__dict__[self.name] = self.func(instance)
  File "/Library/Python/2.7/site-packages/django/template/engine.py", line 106, in template_loaders
    return self.get_template_loaders(self.loaders)
  File "/Library/Python/2.7/site-packages/django/template/engine.py", line 111, in get_template_loaders
    loader = self.find_template_loader(template_loader)
  File "/Library/Python/2.7/site-packages/django/template/engine.py", line 125, in find_template_loader
    return loader_class(self, *args)
  File "/Library/Python/2.7/site-packages/django/template/loaders/cached.py", line 24, in __init__
    self.loaders = engine.get_template_loaders(loaders)
  File "/Library/Python/2.7/site-packages/django/template/engine.py", line 111, in get_template_loaders
    loader = self.find_template_loader(template_loader)
  File "/Library/Python/2.7/site-packages/django/template/engine.py", line 124, in find_template_loader
    loader_class = import_string(loader)
  File "/Library/Python/2.7/site-packages/django/utils/module_loading.py", line 20, in import_string
    module = import_module(module_path)
  File "/System/Library/Frameworks/Python.framework/Versions/2.7/lib/python2.7/importlib/__init__.py", line 37, in import_module
    __import__(name)
ImportError: No module named path.to.custom
